<?xml version="1.0"?>

<robot name="camhand"
       xmlns:xacro="http://www.ros.org/wiki/xacro">

  <xacro:macro name="finger" params="idx x y z r p yaw side">
    <link name="${side}_f${idx}_base">
      <origin xyz="0 0 0" rpy="0 0 0"/>
      <inertial>
        <mass value="0.1"/>
        <origin xyz="0 0 0"/>
        <inertia ixx="0.01" ixy="0" ixz="0" iyy="0.01" iyz="0" izz="0.01"/>
      </inertial>
    </link>
    <link name="${side}_f${idx}_fixed_accel">
      <origin xyz="0 0 0" rpy="0 0 0"/>
      <inertial>
        <mass value="0.1"/>
        <origin xyz="0 0 0"/>
        <inertia ixx="0.01" ixy="0" ixz="0" iyy="0.01" iyz="0" izz="0.01"/>
      </inertial>
    </link>
    <link name="${side}_f${idx}_0">
      <origin xyz="0 0 0" rpy="0 0 0"/>
      <inertial>
        <mass value="0.1"/>
        <origin xyz="0 0 0"/>
        <inertia ixx="0.01" ixy="0" ixz="0" iyy="0.01" iyz="0" izz="0.01"/>
      </inertial>
      <collision>
        <origin xyz="0 0 0" rpy="0 0 0"/>
        <geometry>
          <mesh filename="model://camhand/meshes/f0.stl"/>
        </geometry>
      </collision>
      <visual>
        <origin xyz="0 0 0" rpy="0 0 0"/>
        <geometry>
          <mesh filename="model://camhand/meshes/f0.stl"/>
        </geometry>
        <material name="${side}_camhand_skin_suntan">
          <color rgba="0.7 0.4 0.2 1.0"/>
        </material>
      </visual>
    </link>
    <link name="${side}_f${idx}_1">
      <origin xyz="0 0 0" rpy="0 0 0"/>
      <inertial>
        <mass value="0.1"/>
        <origin xyz="0 0 0"/>
        <inertia ixx="0.01" ixy="0" ixz="0" iyy="0.01" iyz="0" izz="0.01"/>
      </inertial>
      <collision>
        <origin xyz="0 0 0" rpy="0 0 0"/>
        <geometry>
          <mesh filename="model://camhand/meshes/f1.stl"/>
        </geometry>
      </collision>
      <visual>
        <origin xyz="0 0 0" rpy="0 0 0"/>
        <geometry>
          <mesh filename="model://camhand/meshes/f1.stl"/>
        </geometry>
        <material name="${side}_camhand_skin">
          <color rgba="0.835 0.655 0.345 1.0"/>
        </material>
      </visual>
    </link>
    <link name="${side}_f${idx}_1_accel">
      <origin xyz="0 0 0" rpy="0 0 0"/>
      <inertial>
        <mass value="0.1"/>
        <origin xyz="0 0 0"/>
        <inertia ixx="0.01" ixy="0" ixz="0" iyy="0.01" iyz="0" izz="0.01"/>
      </inertial>
    </link>
    <link name="${side}_f${idx}_2">
      <origin xyz="0 0 0" rpy="0 0 0"/>
      <inertial>
        <mass value="0.1"/>
        <origin xyz="0 0 0"/>
        <inertia ixx="0.01" ixy="0" ixz="0" iyy="0.01" iyz="0" izz="0.01"/>
      </inertial>
      <collision>
        <origin xyz="0 0 0" rpy="0 0 0"/>
        <geometry>
          <mesh filename="model://camhand/meshes/f2.stl"/>
        </geometry>
      </collision>
      <visual>
        <origin xyz="0 0 0" rpy="0 0 0"/>
        <geometry>
          <mesh filename="model://camhand/meshes/f2.stl"/>
        </geometry>
        <material name="${side}_camhand_skin_suntan">
          <color rgba="0.8 0.6 0.3 1.0"/>
        </material>
      </visual>
    </link>
    <link name="${side}_f${idx}_2_accel">
      <origin xyz="0 0 0" rpy="0 0 0"/>
      <inertial>
        <mass value="0.1"/>
        <origin xyz="0 0 0"/>
        <inertia ixx="0.01" ixy="0" ixz="0" iyy="0.01" iyz="0" izz="0.01"/>
      </inertial>
    </link>

    <joint name="${side}_f${idx}_base" type="fixed">
      <parent link="${side}_palm"/>
      <child link="${side}_f${idx}_base"/>
      <origin xyz="${x} ${y} ${z}" rpy="${r} ${p} ${yaw}"/>
    </joint>
    <joint name="${side}_f${idx}_j0" type="revolute">
      <axis xyz="0 0 1"/>
      <parent link="${side}_f${idx}_base"/>
      <child link="${side}_f${idx}_0"/>
      <limit lower="-1.57079" upper="1.57079" effort="1" velocity="1"/>
      <origin xyz="0 0 0" rpy="0 0 0"/>
    </joint>
    <joint name="${side}_f${idx}_j1" type="revolute">
      <axis xyz="0 0 1"/>
      <parent link="${side}_f${idx}_0"/>
      <child link="${side}_f${idx}_1"/>
      <limit lower="-1.57079" upper="1.57079" effort="1" velocity="1"/>
      <origin xyz="0.028 0 0" rpy="1.57079 0 0"/>
    </joint>
    <joint name="${side}_f${idx}_j2" type="revolute">
      <axis xyz="0 0 1"/>
      <parent link="${side}_f${idx}_1"/>
      <child link="${side}_f${idx}_2"/>
      <origin xyz="0.05 0 0" rpy="0 0 0"/>
      <limit lower="-1.57079" upper="1.57079" effort="1" velocity="1"/>
    </joint>

    <joint name="${side}_f${idx}_fixed_accel" type="fixed">
      <parent link="${side}_f${idx}_base"/>
      <child link="${side}_f${idx}_fixed_accel"/>
      <origin xyz="-0.05 0 0" rpy="0 0 0"/>
    </joint>
    <joint name="${side}_f${idx}_1_accel" type="fixed">
      <parent link="${side}_f${idx}_1"/>
      <child link="${side}_f${idx}_1_accel"/>
      <origin xyz="0.03 0 0" rpy="-1.5709 0 0"/>
    </joint>
    <joint name="${side}_f${idx}_2_accel" type="fixed">
      <parent link="${side}_f${idx}_2"/>
      <child link="${side}_f${idx}_2_accel"/>
      <origin xyz="0.04 0 0" rpy="-1.5709 0 0"/>
    </joint>

  </xacro:macro>

  <xacro:macro name="camhand" params="side parent *origin">
    <link name="${side}_palm">
      <origin xyz="0 0 0" rpy="0 0 0"/>
      <inertial>
        <mass value="0.1"/>
        <origin xyz="0 0 0"/>
        <inertia ixx="0.01" ixy="0" ixz="0" iyy="0.01" iyz="0" izz="0.01"/>
      </inertial>
      <collision>
        <origin xyz="0 0 0" rpy="0 0 0"/>
        <geometry>
          <mesh filename="model://camhand/meshes/palm.stl"/>
        </geometry>
      </collision>
      <visual>
        <origin xyz="0 0 0" rpy="0 0 0"/>
        <geometry>
          <mesh filename="model://camhand/meshes/palm.stl"/>
        </geometry>
        <material name="${side}_camhand_skin">
          <color rgba="0.835 0.655 0.345 1.0"/>
        </material>
      </visual>
    </link>

    <joint name="${side}_camhand_joint" type="fixed">
      <parent link="${parent}"/>
      <child link="${side}_palm"/>
      <insert_block name="origin" />
    </joint>

    <xacro:finger side="${side}" idx="0" x="0.140" y="0.00000" z="0" r="0" p="0" yaw="0.3"/>
    <xacro:finger side="${side}" idx="1" x="0.115" y="0.03122" z="0" r="0" p="0" yaw="0.3"/>
    <xacro:finger side="${side}" idx="2" x="0.090" y="0.06245" z="0" r="0" p="0" yaw="0.3"/>
    <xacro:finger side="${side}" idx="3" x="0.03995" y="-0.04383" z="0.014" r="0" p="-1.57079" yaw="-2.3562"/>
  </xacro:macro>
</robot>

