<?xml version="1.0" ?>
<!-- =================================================================================== -->
<!-- |    This document was autogenerated by xacro from drc_robot.model.xacro          | -->
<!-- |    EDITING THIS FILE BY HAND IS NOT RECOMMENDED                                 | -->
<!-- =================================================================================== -->
<robot name="drc_robot" xmlns:controller="http://playerstage.sourceforge.net/gazebo/xmlschema/#controller" xmlns:interface="http://playerstage.sourceforge.net/gazebo/xmlschema/#interface" xmlns:sensor="http://playerstage.sourceforge.net/gazebo/xmlschema/#sensor" xmlns:xacro="http://www.ros.org/wiki/xacro">
  <link name="head">
    <inertial>
      <mass value="2.6"/>
      <origin rpy="0 -0 0" xyz="-0.004 0 0.056"/>
      <inertia ixx="0.009" ixy="0" ixz="0" iyy="0.006" iyz="0" izz="0.007"/>
    </inertial>
    <visual>
      <origin rpy="0 -0 0" xyz="0 0 0"/>
      <geometry>
        <mesh filename="model://drc_robot/meshes/head.dae" scale="1 1 1"/>
      </geometry>
    </visual>
    <collision>
      <origin rpy="0 -0 0" xyz="0 0 0"/>
      <geometry>
        <mesh filename="model://drc_robot/meshes/head.stl" scale="1 1 1"/>
      </geometry>
    </collision>
  </link>
  <link name="l_clav">
    <inertial>
      <mass value="2.369"/>
      <origin rpy="0 -0 0" xyz="0.014 0.058 0.029"/>
      <inertia ixx="0.004" ixy="0.001" ixz="0" iyy="0.006" iyz="0" izz="0.007"/>
    </inertial>
    <visual>
      <origin rpy="0 -0 0" xyz="0 0 0"/>
      <geometry>
        <mesh filename="model://drc_robot/meshes/l_clav.dae" scale="1 1 1"/>
      </geometry>
    </visual>
    <collision>
      <origin rpy="0 -0 0" xyz="0 0 0"/>
      <geometry>
        <mesh filename="model://drc_robot/meshes/l_clav.stl" scale="1 1 1"/>
      </geometry>
    </collision>
  </link>
  <link name="l_farm">
    <inertial>
      <mass value="0.981"/>
      <origin rpy="0 -0 0" xyz="0 0.041 0"/>
      <inertia ixx="0.003" ixy="0" ixz="0" iyy="0.001" iyz="0" izz="0.003"/>
    </inertial>
    <visual>
      <origin rpy="0 -0 0" xyz="0 0 0"/>
      <geometry>
        <mesh filename="model://drc_robot/meshes/l_farm.dae" scale="1 1 1"/>
      </geometry>
    </visual>
    <collision>
      <origin rpy="0 -0 0" xyz="0 0 0"/>
      <geometry>
        <mesh filename="model://drc_robot/meshes/l_farm.stl" scale="1 1 1"/>
      </geometry>
    </collision>
  </link>
  <link name="l_foot">
    <inertial>
      <mass value="1.634"/>
      <origin rpy="0 -0 0" xyz="0.027 0 -0.067"/>
      <inertia ixx="0.002" ixy="0" ixz="0" iyy="0.007" iyz="0" izz="0.008"/>
    </inertial>
    <visual>
      <origin rpy="0 -0 0" xyz="0 0 0"/>
      <geometry>
        <mesh filename="model://drc_robot/meshes/l_foot.dae" scale="1 1 1"/>
      </geometry>
    </visual>
    <collision>
      <origin rpy="0 -0 0" xyz="0 0 0"/>
      <geometry>
        <mesh filename="model://drc_robot/meshes/l_foot.stl" scale="1 1 1"/>
      </geometry>
    </collision>
  </link>
  <link name="l_hand">
    <inertial>
      <mass value="2.263"/>
      <origin rpy="0 -0 0" xyz="0 0.093 0"/>
      <inertia ixx="0.01" ixy="0" ixz="0" iyy="0.002" iyz="0" izz="0.01"/>
    </inertial>
    <visual>
      <origin rpy="0 -0 0" xyz="0 0 0"/>
      <geometry>
        <mesh filename="model://drc_robot/meshes/l_hand.dae" scale="1 1 1"/>
      </geometry>
    </visual>
    <collision>
      <origin rpy="0 -0 0" xyz="0 0 0"/>
      <geometry>
        <mesh filename="model://drc_robot/meshes/l_hand.stl" scale="1 1 1"/>
      </geometry>
    </collision>
  </link>
  <link name="l_larm">
    <inertial>
      <mass value="2.148"/>
      <origin rpy="0 -0 0" xyz="-0.003 0.099 -0.014"/>
      <inertia ixx="0.005" ixy="0" ixz="0" iyy="0.003" iyz="0" izz="0.006"/>
    </inertial>
    <visual>
      <origin rpy="0 -0 0" xyz="0 0 0"/>
      <geometry>
        <mesh filename="model://drc_robot/meshes/l_larm.dae" scale="1 1 1"/>
      </geometry>
    </visual>
    <collision>
      <origin rpy="0 -0 0" xyz="0 0 0"/>
      <geometry>
        <mesh filename="model://drc_robot/meshes/l_larm.stl" scale="1 1 1"/>
      </geometry>
    </collision>
  </link>
  <link name="l_lglut">
    <inertial>
      <mass value="0.69"/>
      <origin rpy="0 -0 0" xyz="0.0133341 0.0170484 -0.0312052"/>
      <inertia ixx="0.000691326" ixy="-2.24344e-05" ixz="2.50508e-06" iyy="0.00126856" iyz="0.000137862" izz="0.00106487"/>
    </inertial>
    <visual>
      <origin rpy="0 -0 0" xyz="0 0 0"/>
      <geometry>
        <mesh filename="model://drc_robot/meshes/l_lglut.dae" scale="1 1 1"/>
      </geometry>
    </visual>
    <collision>
      <origin rpy="0 -0 0" xyz="0 0 0"/>
      <geometry>
        <mesh filename="model://drc_robot/meshes/l_lglut.stl" scale="1 1 1"/>
      </geometry>
    </collision>
  </link>
  <link name="l_lleg">
    <inertial>
      <mass value="4.367"/>
      <origin rpy="0 -0 0" xyz="0.001 0 -0.187"/>
      <inertia ixx="0.077" ixy="0" ixz="-0.003" iyy="0.076" iyz="0" izz="0.01"/>
    </inertial>
    <visual>
      <origin rpy="0 -0 0" xyz="0 0 0"/>
      <geometry>
        <mesh filename="model://drc_robot/meshes/l_lleg.dae" scale="1 1 1"/>
      </geometry>
    </visual>
    <collision>
      <origin rpy="0 -0 0" xyz="0 0 0"/>
      <geometry>
        <mesh filename="model://drc_robot/meshes/l_lleg.stl" scale="1 1 1"/>
      </geometry>
    </collision>
  </link>
  <link name="l_scap">
    <inertial>
      <mass value="2.707"/>
      <origin rpy="0 -0 0" xyz="-0.002 0.108 0"/>
      <inertia ixx="0.01" ixy="0" ixz="0" iyy="0.005" iyz="0" izz="0.013"/>
    </inertial>
    <visual>
      <origin rpy="0 -0 0" xyz="0 0 0"/>
      <geometry>
        <mesh filename="model://drc_robot/meshes/l_scap.dae" scale="1 1 1"/>
      </geometry>
    </visual>
    <collision>
      <origin rpy="0 -0 0" xyz="0 0 0"/>
      <geometry>
        <mesh filename="model://drc_robot/meshes/l_scap.stl" scale="1 1 1"/>
      </geometry>
    </collision>
  </link>
  <link name="l_talus">
    <inertial>
      <mass value="0.1"/>
      <origin rpy="0 -0 0" xyz="0 0 0"/>
      <inertia ixx="1.01674e-05" ixy="0" ixz="0" iyy="8.42775e-06" iyz="0" izz="1.30101e-05"/>
    </inertial>
    <visual>
      <origin rpy="0 -0 0" xyz="0 0 0"/>
      <geometry>
        <mesh filename="model://drc_robot/meshes/l_talus.dae" scale="1 1 1"/>
      </geometry>
    </visual>
    <collision>
      <origin rpy="0 -0 0" xyz="0 0 0"/>
      <geometry>
        <mesh filename="model://drc_robot/meshes/l_talus.stl" scale="1 1 1"/>
      </geometry>
    </collision>
  </link>
  <link name="l_uarm">
    <inertial>
      <mass value="1.881"/>
      <origin rpy="0 -0 0" xyz="0.007 0.114 0.008"/>
      <inertia ixx="0.002" ixy="0" ixz="0" iyy="0.003" iyz="0" izz="0.003"/>
    </inertial>
    <visual>
      <origin rpy="0 -0 0" xyz="0 0 0"/>
      <geometry>
        <mesh filename="model://drc_robot/meshes/l_uarm.dae" scale="1 1 1"/>
      </geometry>
    </visual>
    <collision>
      <origin rpy="0 -0 0" xyz="0 0 0"/>
      <geometry>
        <mesh filename="model://drc_robot/meshes/l_uarm.stl" scale="1 1 1"/>
      </geometry>
    </collision>
  </link>
  <link name="l_uglut">
    <inertial>
      <mass value="0.5166"/>
      <origin rpy="0 -0 0" xyz="0.00529262 -0.00344732 0.00313046"/>
      <inertia ixx="0.00074276" ixy="-3.79607e-08" ixz="-2.79549e-05" iyy="0.000688179" iyz="-3.2735e-08" izz="0.00041242"/>
    </inertial>
    <visual>
      <origin rpy="0 -0 0" xyz="0 0 0"/>
      <geometry>
        <mesh filename="model://drc_robot/meshes/l_uglut.dae" scale="1 1 1"/>
      </geometry>
    </visual>
    <collision>
      <origin rpy="0 -0 0" xyz="0 0 0"/>
      <geometry>
        <mesh filename="model://drc_robot/meshes/l_uglut.stl" scale="1 1 1"/>
      </geometry>
    </collision>
  </link>
  <link name="l_uleg">
    <inertial>
      <mass value="7.34"/>
      <origin rpy="0 -0 0" xyz="0 0 -0.21"/>
      <inertia ixx="0.09" ixy="0" ixz="0" iyy="0.09" iyz="0" izz="0.02"/>
    </inertial>
    <visual>
      <origin rpy="0 -0 0" xyz="0 0 0"/>
      <geometry>
        <mesh filename="model://drc_robot/meshes/l_uleg.dae" scale="1 1 1"/>
      </geometry>
    </visual>
    <collision>
      <origin rpy="0 -0 0" xyz="0 0 0"/>
      <geometry>
        <mesh filename="model://drc_robot/meshes/l_uleg.stl" scale="1 1 1"/>
      </geometry>
    </collision>
  </link>
  <link name="ltorso">
    <inertial>
      <mass value="1.92"/>
      <origin rpy="0 -0 0" xyz="-0.0112984 -3.15366e-06 0.0746835"/>
      <inertia ixx="0.0039092" ixy="-5.04491e-08" ixz="-0.000342157" iyy="0.00341694" iyz="4.87119e-07" izz="0.00174492"/>
    </inertial>
    <visual>
      <origin rpy="0 -0 0" xyz="0 0 0"/>
      <geometry>
        <mesh filename="model://drc_robot/meshes/ltorso.dae" scale="1 1 1"/>
      </geometry>
    </visual>
    <collision>
      <origin rpy="0 -0 0" xyz="0 0 0"/>
      <geometry>
        <mesh filename="model://drc_robot/meshes/ltorso.stl" scale="1 1 1"/>
      </geometry>
    </collision>
  </link>
  <link name="mtorso">
    <inertial>
      <mass value="0.55"/>
      <origin rpy="0 -0 0" xyz="-0.00816266 -0.0131245 0.0305974"/>
      <inertia ixx="0.000454181" ixy="-6.10764e-05" ixz="3.94009e-05" iyy="0.000483282" iyz="5.27463e-05" izz="0.000444215"/>
    </inertial>
    <visual>
      <origin rpy="0 -0 0" xyz="0 0 0"/>
      <geometry>
        <mesh filename="model://drc_robot/meshes/mtorso.dae" scale="1 1 1"/>
      </geometry>
    </visual>
    <collision>
      <origin rpy="0 -0 0" xyz="0 0 0"/>
      <geometry>
        <mesh filename="model://drc_robot/meshes/mtorso.stl" scale="1 1 1"/>
      </geometry>
    </collision>
  </link>
  <link name="pelvis">
    <inertial>
      <mass value="14.2529"/>
      <origin rpy="0 -0 0" xyz="0.0111 0 0.0271"/>
      <inertia ixx="0.1244" ixy="0.0008" ixz="-0.0007" iyy="0.0958" iyz="-0.0005" izz="0.1167"/>
    </inertial>
    <visual>
      <origin rpy="0 -0 0" xyz="0 0 0"/>
      <geometry>
        <mesh filename="model://drc_robot/meshes/pelvis.dae" scale="1 1 1"/>
      </geometry>
    </visual>
    <collision>
      <origin rpy="0 -0 0" xyz="0 0 0"/>
      <geometry>
        <mesh filename="model://drc_robot/meshes/pelvis.stl" scale="1 1 1"/>
      </geometry>
    </collision>
  </link>
  <link name="r_clav">
    <inertial>
      <mass value="2.369"/>
      <origin rpy="0 -0 0" xyz="0.014 -0.058 0.029"/>
      <inertia ixx="0.004" ixy="-0.001" ixz="0" iyy="0.006" iyz="0" izz="0.007"/>
    </inertial>
    <visual>
      <origin rpy="0 -0 0" xyz="0 0 0"/>
      <geometry>
        <mesh filename="model://drc_robot/meshes/r_clav.dae" scale="1 1 1"/>
      </geometry>
    </visual>
    <collision>
      <origin rpy="0 -0 0" xyz="0 0 0"/>
      <geometry>
        <mesh filename="model://drc_robot/meshes/r_clav.stl" scale="1 1 1"/>
      </geometry>
    </collision>
  </link>
  <link name="r_farm">
    <inertial>
      <mass value="0.981"/>
      <origin rpy="0 -0 0" xyz="0 -0.041 0"/>
      <inertia ixx="0.003" ixy="0" ixz="0" iyy="0.001" iyz="0" izz="0.003"/>
    </inertial>
    <visual>
      <origin rpy="0 -0 0" xyz="0 0 0"/>
      <geometry>
        <mesh filename="model://drc_robot/meshes/r_farm.dae" scale="1 1 1"/>
      </geometry>
    </visual>
    <collision>
      <origin rpy="0 -0 0" xyz="0 0 0"/>
      <geometry>
        <mesh filename="model://drc_robot/meshes/r_farm.stl" scale="1 1 1"/>
      </geometry>
    </collision>
  </link>
  <link name="r_foot">
    <inertial>
      <mass value="1.634"/>
      <origin rpy="0 -0 0" xyz="0.027 0 -0.067"/>
      <inertia ixx="0.002" ixy="0" ixz="0" iyy="0.007" iyz="0" izz="0.008"/>
    </inertial>
    <visual>
      <origin rpy="0 -0 0" xyz="0 0 0"/>
      <geometry>
        <mesh filename="model://drc_robot/meshes/r_foot.dae" scale="1 1 1"/>
      </geometry>
    </visual>
    <collision>
      <origin rpy="0 -0 0" xyz="0 0 0"/>
      <geometry>
        <mesh filename="model://drc_robot/meshes/r_foot.stl" scale="1 1 1"/>
      </geometry>
    </collision>
  </link>
  <link name="r_hand">
    <inertial>
      <mass value="2.263"/>
      <origin rpy="0 -0 0" xyz="0 -0.093 0"/>
      <inertia ixx="0.01" ixy="0" ixz="0" iyy="0.002" iyz="0" izz="0.01"/>
    </inertial>
    <visual>
      <origin rpy="0 -0 0" xyz="0 0 0"/>
      <geometry>
        <mesh filename="model://drc_robot/meshes/r_hand.dae" scale="1 1 1"/>
      </geometry>
    </visual>
    <collision>
      <origin rpy="0 -0 0" xyz="0 0 0"/>
      <geometry>
        <mesh filename="model://drc_robot/meshes/r_hand.stl" scale="1 1 1"/>
      </geometry>
    </collision>
  </link>
  <link name="r_larm">
    <inertial>
      <mass value="2.148"/>
      <origin rpy="0 -0 0" xyz="-0.003 -0.099 -0.014"/>
      <inertia ixx="0.005" ixy="0" ixz="0" iyy="0.003" iyz="0" izz="0.006"/>
    </inertial>
    <visual>
      <origin rpy="0 -0 0" xyz="0 0 0"/>
      <geometry>
        <mesh filename="model://drc_robot/meshes/r_larm.dae" scale="1 1 1"/>
      </geometry>
    </visual>
    <collision>
      <origin rpy="0 -0 0" xyz="0 0 0"/>
      <geometry>
        <mesh filename="model://drc_robot/meshes/r_larm.stl" scale="1 1 1"/>
      </geometry>
    </collision>
  </link>
  <link name="r_lglut">
    <inertial>
      <mass value="0.69"/>
      <origin rpy="0 -0 0" xyz="0.0133341 -0.0170484 -0.0312052"/>
      <inertia ixx="0.000691326" ixy="2.24344e-05" ixz="2.50508e-06" iyy="0.00126856" iyz="-0.000137862" izz="0.00106487"/>
    </inertial>
    <visual>
      <origin rpy="0 -0 0" xyz="0 0 0"/>
      <geometry>
        <mesh filename="model://drc_robot/meshes/r_lglut.dae" scale="1 1 1"/>
      </geometry>
    </visual>
    <collision>
      <origin rpy="0 -0 0" xyz="0 0 0"/>
      <geometry>
        <mesh filename="model://drc_robot/meshes/r_lglut.stl" scale="1 1 1"/>
      </geometry>
    </collision>
  </link>
  <link name="r_lleg">
    <inertial>
      <mass value="4.367"/>
      <origin rpy="0 -0 0" xyz="0.001 0 -0.187"/>
      <inertia ixx="0.077" ixy="-0" ixz="-0.003" iyy="0.076" iyz="-0" izz="0.01"/>
    </inertial>
    <visual>
      <origin rpy="0 -0 0" xyz="0 0 0"/>
      <geometry>
        <mesh filename="model://drc_robot/meshes/r_lleg.dae" scale="1 1 1"/>
      </geometry>
    </visual>
    <collision>
      <origin rpy="0 -0 0" xyz="0 0 0"/>
      <geometry>
        <mesh filename="model://drc_robot/meshes/r_lleg.stl" scale="1 1 1"/>
      </geometry>
    </collision>
  </link>
  <link name="r_scap">
    <inertial>
      <mass value="2.707"/>
      <origin rpy="0 -0 0" xyz="-0.002 -0.108 0"/>
      <inertia ixx="0.01" ixy="0" ixz="0" iyy="0.005" iyz="0" izz="0.013"/>
    </inertial>
    <visual>
      <origin rpy="0 -0 0" xyz="0 0 0"/>
      <geometry>
        <mesh filename="model://drc_robot/meshes/r_scap.dae" scale="1 1 1"/>
      </geometry>
    </visual>
    <collision>
      <origin rpy="0 -0 0" xyz="0 0 0"/>
      <geometry>
        <mesh filename="model://drc_robot/meshes/r_scap.stl" scale="1 1 1"/>
      </geometry>
    </collision>
  </link>
  <link name="r_talus">
    <inertial>
      <mass value="0.1"/>
      <origin rpy="0 -0 0" xyz="0 0 0"/>
      <inertia ixx="1.01674e-05" ixy="0" ixz="0" iyy="8.42775e-06" iyz="0" izz="1.30101e-05"/>
    </inertial>
    <visual>
      <origin rpy="0 -0 0" xyz="0 0 0"/>
      <geometry>
        <mesh filename="model://drc_robot/meshes/r_talus.dae" scale="1 1 1"/>
      </geometry>
    </visual>
    <collision>
      <origin rpy="0 -0 0" xyz="0 0 0"/>
      <geometry>
        <mesh filename="model://drc_robot/meshes/r_talus.stl" scale="1 1 1"/>
      </geometry>
    </collision>
  </link>
  <link name="r_uarm">
    <inertial>
      <mass value="1.881"/>
      <origin rpy="0 -0 0" xyz="0.007 -0.114 0.008"/>
      <inertia ixx="0.002" ixy="0" ixz="0" iyy="0.003" iyz="0" izz="0.003"/>
    </inertial>
    <visual>
      <origin rpy="0 -0 0" xyz="0 0 0"/>
      <geometry>
        <mesh filename="model://drc_robot/meshes/r_uarm.dae" scale="1 1 1"/>
      </geometry>
    </visual>
    <collision>
      <origin rpy="0 -0 0" xyz="0 0 0"/>
      <geometry>
        <mesh filename="model://drc_robot/meshes/r_uarm.stl" scale="1 1 1"/>
      </geometry>
    </collision>
  </link>
  <link name="r_uglut">
    <inertial>
      <mass value="0.5166"/>
      <origin rpy="0 -0 0" xyz="0.00529262 0.00344732 0.00313046"/>
      <inertia ixx="0.00074276" ixy="3.79607e-08" ixz="-2.79549e-05" iyy="0.000688179" iyz="3.2735e-08" izz="0.00041242"/>
    </inertial>
    <visual>
      <origin rpy="0 -0 0" xyz="0 0 0"/>
      <geometry>
        <mesh filename="model://drc_robot/meshes/r_uglut.dae" scale="1 1 1"/>
      </geometry>
    </visual>
    <collision>
      <origin rpy="0 -0 0" xyz="0 0 0"/>
      <geometry>
        <mesh filename="model://drc_robot/meshes/r_uglut.stl" scale="1 1 1"/>
      </geometry>
    </collision>
  </link>
  <link name="r_uleg">
    <inertial>
      <mass value="7.34"/>
      <origin rpy="0 -0 0" xyz="0 0 -0.21"/>
      <inertia ixx="0.09" ixy="0" ixz="0" iyy="0.09" iyz="0" izz="0.02"/>
    </inertial>
    <visual>
      <origin rpy="0 -0 0" xyz="0 0 0"/>
      <geometry>
        <mesh filename="model://drc_robot/meshes/r_uleg.dae" scale="1 1 1"/>
      </geometry>
    </visual>
    <collision>
      <origin rpy="0 -0 0" xyz="0 0 0"/>
      <geometry>
        <mesh filename="model://drc_robot/meshes/r_uleg.stl" scale="1 1 1"/>
      </geometry>
    </collision>
  </link>
  <link name="utorso">
    <inertial>
      <mass value="18.484"/>
      <origin rpy="0 -0 0" xyz="0.02 -0.001 0.211"/>
      <inertia ixx="0.395" ixy="0" ixz="0.083" iyy="1.089" iyz="-0.003" izz="0.327"/>
    </inertial>
    <visual>
      <origin rpy="0 -0 0" xyz="0 0 0"/>
      <geometry>
        <mesh filename="model://drc_robot/meshes/utorso.dae" scale="1 1 1"/>
      </geometry>
    </visual>
    <collision>
      <origin rpy="0 -0 0" xyz="0 0 0"/>
      <geometry>
        <mesh filename="model://drc_robot/meshes/utorso.stl" scale="1 1 1"/>
      </geometry>
    </collision>
  </link>
  <joint name="back.lbz" type="revolute">
    <origin rpy="0 -0 0" xyz="-0.0125 0 0"/>
    <axis xyz="0 0 1"/>
    <parent link="pelvis"/>
    <child link="ltorso"/>
    <limit effort="124.016" lower="-0.610865" upper="0.610865" velocity="12"/>
  </joint>
  <joint name="back.mby" type="revolute">
    <origin rpy="0 -0 0" xyz="0 0 0.14"/>
    <axis xyz="0 1 0"/>
    <parent link="ltorso"/>
    <child link="mtorso"/>
    <limit effort="206.843" lower="-1.2" upper="1.28" velocity="12"/>
  </joint>
  <joint name="back.ubx" type="revolute">
    <origin rpy="0 -0 0" xyz="0 0 0.05"/>
    <axis xyz="1 0 0"/>
    <parent link="mtorso"/>
    <child link="utorso"/>
    <limit effort="94.91" lower="-0.790809" upper="0" velocity="12"/>
  </joint>
  <joint name="l.arm.elx" type="revolute">
    <origin rpy="0 -0 0" xyz="0 0.121 0.013"/>
    <axis xyz="1 0 0"/>
    <parent link="l_uarm"/>
    <child link="l_larm"/>
    <limit effort="114" lower="0" upper="2.35619" velocity="12"/>
  </joint>
  <joint name="l.arm.ely" type="revolute">
    <origin rpy="0 -0 0" xyz="0 0.185 0"/>
    <axis xyz="0 1 0"/>
    <parent link="l_scap"/>
    <child link="l_uarm"/>
    <limit effort="114" lower="0" upper="3.14159" velocity="12"/>
  </joint>
  <joint name="l.arm.mwx" type="revolute">
    <origin rpy="0 -0 0" xyz="0 0.095 0"/>
    <axis xyz="1 0 0"/>
    <parent link="l_farm"/>
    <child link="l_hand"/>
    <limit effort="60" lower="-0.436" upper="1.571" velocity="12"/>
  </joint>
  <joint name="l.arm.shx" type="revolute">
    <origin rpy="0 -0 0" xyz="0 0.075 0.036"/>
    <axis xyz="1 0 0"/>
    <parent link="l_clav"/>
    <child link="l_scap"/>
    <limit effort="170" lower="-1.39626" upper="1.74533" velocity="12"/>
  </joint>
  <joint name="l.arm.usy" type="revolute">
    <origin rpy="0 -0 0" xyz="0.024 0.221 0.289"/>
    <axis xyz="0 -0.5 0.866025"/>
    <parent link="utorso"/>
    <child link="l_clav"/>
    <limit effort="212" lower="-1.9635" upper="1.9635" velocity="12"/>
  </joint>
  <joint name="l.arm.uwy" type="revolute">
    <origin rpy="0 -0 0" xyz="0 0.183 -0.013"/>
    <axis xyz="0 1 0"/>
    <parent link="l_larm"/>
    <child link="l_farm"/>
    <limit effort="114" lower="-1.571" upper="1.571" velocity="12"/>
  </joint>
  <joint name="l.leg.kny" type="revolute">
    <origin rpy="0 -0 0" xyz="-0.05 0 -0.374"/>
    <axis xyz="0 1 0"/>
    <parent link="l_uleg"/>
    <child link="l_lleg"/>
    <limit effort="220" lower="0" upper="2.45" velocity="12"/>
  </joint>
  <joint name="l.leg.lax" type="revolute">
    <origin rpy="0 -0 0" xyz="0 0 0"/>
    <axis xyz="1 0 0"/>
    <parent link="l_talus"/>
    <child link="l_foot"/>
    <limit effort="90" lower="-0.436" upper="0.436" velocity="12"/>
  </joint>
  <joint name="l.leg.lhy" type="revolute">
    <origin rpy="0 -0 0" xyz="0.05 0 -0.05"/>
    <axis xyz="0 1 0"/>
    <parent link="l_lglut"/>
    <child link="l_uleg"/>
    <limit effort="260" lower="-1.75" upper="0.524" velocity="12"/>
  </joint>
  <joint name="l.leg.mhx" type="revolute">
    <origin rpy="0 -0 0" xyz="0 0 0"/>
    <axis xyz="1 0 0"/>
    <parent link="l_uglut"/>
    <child link="l_lglut"/>
    <limit effort="180" lower="-0.47" upper="0.495" velocity="12"/>
  </joint>
  <joint name="l.leg.uay" type="revolute">
    <origin rpy="0 -0 0" xyz="0 0 -0.422"/>
    <axis xyz="0 1 0"/>
    <parent link="l_lleg"/>
    <child link="l_talus"/>
    <limit effort="220" lower="-0.698" upper="0.698" velocity="12"/>
  </joint>
  <joint name="l.leg.uhz" type="revolute">
    <origin rpy="0 -0 0" xyz="0 0.089 0"/>
    <axis xyz="0 0 1"/>
    <parent link="pelvis"/>
    <child link="l_uglut"/>
    <limit effort="110" lower="-0.32" upper="1.14" velocity="12"/>
  </joint>
  <joint name="neck.ay" type="revolute">
    <origin rpy="0 -0 0" xyz="0.011 0 0.49"/>
    <axis xyz="0 1 0"/>
    <parent link="utorso"/>
    <child link="head"/>
    <limit effort="5" lower="0.785398" upper="0.785398" velocity="12"/>
  </joint>
  <joint name="r.arm.elx" type="revolute">
    <origin rpy="0 -0 0" xyz="0 -0.121 0.013"/>
    <axis xyz="1 0 0"/>
    <parent link="r_uarm"/>
    <child link="r_larm"/>
    <limit effort="114" lower="-2.35619" upper="0" velocity="12"/>
  </joint>
  <joint name="r.arm.ely" type="revolute">
    <origin rpy="0 -0 0" xyz="0 -0.185 0"/>
    <axis xyz="0 1 0"/>
    <parent link="r_scap"/>
    <child link="r_uarm"/>
    <limit effort="114" lower="0" upper="3.14159" velocity="12"/>
  </joint>
  <joint name="r.arm.mwx" type="revolute">
    <origin rpy="0 -0 0" xyz="0 -0.095 0"/>
    <axis xyz="1 0 0"/>
    <parent link="r_farm"/>
    <child link="r_hand"/>
    <limit effort="60" lower="-1.571" upper="0.436" velocity="12"/>
  </joint>
  <joint name="r.arm.shx" type="revolute">
    <origin rpy="0 -0 0" xyz="0 -0.075 0.036"/>
    <axis xyz="1 0 0"/>
    <parent link="r_clav"/>
    <child link="r_scap"/>
    <limit effort="170" lower="-1.74533" upper="1.39626" velocity="12"/>
  </joint>
  <joint name="r.arm.usy" type="revolute">
    <origin rpy="0 -0 0" xyz="0.024 -0.221 0.289"/>
    <axis xyz="0 0.5 0.866025"/>
    <parent link="utorso"/>
    <child link="r_clav"/>
    <limit effort="212" lower="-1.9635" upper="1.9635" velocity="12"/>
  </joint>
  <joint name="r.arm.uwy" type="revolute">
    <origin rpy="0 -0 0" xyz="0 -0.183 -0.013"/>
    <axis xyz="0 1 0"/>
    <parent link="r_larm"/>
    <child link="r_farm"/>
    <limit effort="114" lower="-1.571" upper="1.571" velocity="12"/>
  </joint>
  <joint name="r.leg.kny" type="revolute">
    <origin rpy="0 -0 0" xyz="-0.05 0 -0.374"/>
    <axis xyz="0 1 0"/>
    <parent link="r_uleg"/>
    <child link="r_lleg"/>
    <limit effort="220" lower="0" upper="2.45" velocity="12"/>
  </joint>
  <joint name="r.leg.lax" type="revolute">
    <origin rpy="0 -0 0" xyz="0 0 0"/>
    <axis xyz="1 0 0"/>
    <parent link="r_talus"/>
    <child link="r_foot"/>
    <limit effort="90" lower="-0.436" upper="0.436" velocity="12"/>
  </joint>
  <joint name="r.leg.lhy" type="revolute">
    <origin rpy="0 -0 0" xyz="0.05 0 -0.05"/>
    <axis xyz="0 1 0"/>
    <parent link="r_lglut"/>
    <child link="r_uleg"/>
    <limit effort="260" lower="-1.745" upper="0.524" velocity="12"/>
  </joint>
  <joint name="r.leg.mhx" type="revolute">
    <origin rpy="0 -0 0" xyz="0 0 0"/>
    <axis xyz="1 0 0"/>
    <parent link="r_uglut"/>
    <child link="r_lglut"/>
    <limit effort="180" lower="-0.495" upper="0.47" velocity="12"/>
  </joint>
  <joint name="r.leg.uay" type="revolute">
    <origin rpy="0 -0 0" xyz="0 0 -0.422"/>
    <axis xyz="0 1 0"/>
    <parent link="r_lleg"/>
    <child link="r_talus"/>
    <limit effort="220" lower="-0.698" upper="0.698" velocity="12"/>
  </joint>
  <joint name="r.leg.uhz" type="revolute">
    <origin rpy="0 -0 0" xyz="0 -0.089 0"/>
    <axis xyz="0 0 1"/>
    <parent link="pelvis"/>
    <child link="r_uglut"/>
    <limit effort="260" lower="-1.14" upper="0.32" velocity="12"/>
  </joint>
  <link name="r_palm">
    <origin rpy="0 0 0" xyz="0 0 0"/>
    <inertial>
      <mass value="0.1"/>
      <origin xyz="0 0 0"/>
      <inertia ixx="0.01" ixy="0" ixz="0" iyy="0.01" iyz="0" izz="0.01"/>
    </inertial>
    <collision>
      <origin rpy="0 0 0" xyz="0 0 0"/>
      <geometry>
        <mesh filename="camhand/palm.stl"/>
      </geometry>
    </collision>
    <visual>
      <origin rpy="0 0 0" xyz="0 0 0"/>
      <geometry>
        <mesh filename="camhand/palm.stl"/>
      </geometry>
      <material name="r_camhand_skin">
        <color rgba="0.835 0.655 0.345 1.0"/>
      </material>
    </visual>
  </link>
  <joint name="r_camhand_joint" type="fixed">
    <parent link="r_hand"/>
    <child link="r_palm"/>
    <origin rpy="0 3.1416  1.57079" xyz="0 -0.1 -0.03"/>
  </joint>
  <link name="r_f0_base">
    <origin rpy="0 0 0" xyz="0 0 0"/>
    <inertial>
      <mass value="0.1"/>
      <origin xyz="0 0 0"/>
      <inertia ixx="0.01" ixy="0" ixz="0" iyy="0.01" iyz="0" izz="0.01"/>
    </inertial>
  </link>
  <link name="r_f0_fixed_accel">
    <origin rpy="0 0 0" xyz="0 0 0"/>
    <inertial>
      <mass value="0.1"/>
      <origin xyz="0 0 0"/>
      <inertia ixx="0.01" ixy="0" ixz="0" iyy="0.01" iyz="0" izz="0.01"/>
    </inertial>
  </link>
  <link name="r_f0_0">
    <origin rpy="0 0 0" xyz="0 0 0"/>
    <inertial>
      <mass value="0.1"/>
      <origin xyz="0 0 0"/>
      <inertia ixx="0.01" ixy="0" ixz="0" iyy="0.01" iyz="0" izz="0.01"/>
    </inertial>
    <collision>
      <origin rpy="0 0 0" xyz="0 0 0"/>
      <geometry>
        <mesh filename="camhand/f0.stl"/>
      </geometry>
    </collision>
    <visual>
      <origin rpy="0 0 0" xyz="0 0 0"/>
      <geometry>
        <mesh filename="camhand/f0.stl"/>
      </geometry>
      <material name="r_camhand_skin_suntan">
        <color rgba="0.7 0.4 0.2 1.0"/>
      </material>
    </visual>
  </link>
  <link name="r_f0_1">
    <origin rpy="0 0 0" xyz="0 0 0"/>
    <inertial>
      <mass value="0.1"/>
      <origin xyz="0 0 0"/>
      <inertia ixx="0.01" ixy="0" ixz="0" iyy="0.01" iyz="0" izz="0.01"/>
    </inertial>
    <collision>
      <origin rpy="0 0 0" xyz="0 0 0"/>
      <geometry>
        <mesh filename="camhand/f1.stl"/>
      </geometry>
    </collision>
    <visual>
      <origin rpy="0 0 0" xyz="0 0 0"/>
      <geometry>
        <mesh filename="camhand/f1.stl"/>
      </geometry>
      <material name="r_camhand_skin">
        <color rgba="0.835 0.655 0.345 1.0"/>
      </material>
    </visual>
  </link>
  <link name="r_f0_1_accel">
    <origin rpy="0 0 0" xyz="0 0 0"/>
    <inertial>
      <mass value="0.1"/>
      <origin xyz="0 0 0"/>
      <inertia ixx="0.01" ixy="0" ixz="0" iyy="0.01" iyz="0" izz="0.01"/>
    </inertial>
  </link>
  <link name="r_f0_2">
    <origin rpy="0 0 0" xyz="0 0 0"/>
    <inertial>
      <mass value="0.1"/>
      <origin xyz="0 0 0"/>
      <inertia ixx="0.01" ixy="0" ixz="0" iyy="0.01" iyz="0" izz="0.01"/>
    </inertial>
    <collision>
      <origin rpy="0 0 0" xyz="0 0 0"/>
      <geometry>
        <mesh filename="camhand/f2.stl"/>
      </geometry>
    </collision>
    <visual>
      <origin rpy="0 0 0" xyz="0 0 0"/>
      <geometry>
        <mesh filename="camhand/f2.stl"/>
      </geometry>
      <material name="r_camhand_skin_suntan">
        <color rgba="0.8 0.6 0.3 1.0"/>
      </material>
    </visual>
  </link>
  <link name="r_f0_2_accel">
    <origin rpy="0 0 0" xyz="0 0 0"/>
    <inertial>
      <mass value="0.1"/>
      <origin xyz="0 0 0"/>
      <inertia ixx="0.01" ixy="0" ixz="0" iyy="0.01" iyz="0" izz="0.01"/>
    </inertial>
  </link>
  <joint name="r_f0_base" type="fixed">
    <parent link="r_palm"/>
    <child link="r_f0_base"/>
    <origin rpy="0 0 0.3" xyz="0.14 0.0 0"/>
  </joint>
  <joint name="r_f0_j0" type="revolute">
    <axis xyz="0 0 1"/>
    <parent link="r_f0_base"/>
    <child link="r_f0_0"/>
    <limit effort="1" lower="-1.57079" upper="1.57079" velocity="1"/>
    <origin rpy="0 0 0" xyz="0 0 0"/>
  </joint>
  <joint name="r_f0_j1" type="revolute">
    <axis xyz="0 0 1"/>
    <parent link="r_f0_0"/>
    <child link="r_f0_1"/>
    <limit effort="1" lower="-1.57079" upper="1.57079" velocity="1"/>
    <origin rpy="1.57079 0 0" xyz="0.028 0 0"/>
  </joint>
  <joint name="r_f0_j2" type="revolute">
    <axis xyz="0 0 1"/>
    <parent link="r_f0_1"/>
    <child link="r_f0_2"/>
    <origin rpy="0 0 0" xyz="0.05 0 0"/>
    <limit effort="1" lower="-1.57079" upper="1.57079" velocity="1"/>
  </joint>
  <joint name="r_f0_fixed_accel" type="fixed">
    <parent link="r_f0_base"/>
    <child link="r_f0_fixed_accel"/>
    <origin rpy="0 0 0" xyz="-0.05 0 0"/>
  </joint>
  <joint name="r_f0_1_accel" type="fixed">
    <parent link="r_f0_1"/>
    <child link="r_f0_1_accel"/>
    <origin rpy="-1.5709 0 0" xyz="0.03 0 0"/>
  </joint>
  <joint name="r_f0_2_accel" type="fixed">
    <parent link="r_f0_2"/>
    <child link="r_f0_2_accel"/>
    <origin rpy="-1.5709 0 0" xyz="0.04 0 0"/>
  </joint>
  <link name="r_f1_base">
    <origin rpy="0 0 0" xyz="0 0 0"/>
    <inertial>
      <mass value="0.1"/>
      <origin xyz="0 0 0"/>
      <inertia ixx="0.01" ixy="0" ixz="0" iyy="0.01" iyz="0" izz="0.01"/>
    </inertial>
  </link>
  <link name="r_f1_fixed_accel">
    <origin rpy="0 0 0" xyz="0 0 0"/>
    <inertial>
      <mass value="0.1"/>
      <origin xyz="0 0 0"/>
      <inertia ixx="0.01" ixy="0" ixz="0" iyy="0.01" iyz="0" izz="0.01"/>
    </inertial>
  </link>
  <link name="r_f1_0">
    <origin rpy="0 0 0" xyz="0 0 0"/>
    <inertial>
      <mass value="0.1"/>
      <origin xyz="0 0 0"/>
      <inertia ixx="0.01" ixy="0" ixz="0" iyy="0.01" iyz="0" izz="0.01"/>
    </inertial>
    <collision>
      <origin rpy="0 0 0" xyz="0 0 0"/>
      <geometry>
        <mesh filename="camhand/f0.stl"/>
      </geometry>
    </collision>
    <visual>
      <origin rpy="0 0 0" xyz="0 0 0"/>
      <geometry>
        <mesh filename="camhand/f0.stl"/>
      </geometry>
      <material name="r_camhand_skin_suntan">
        <color rgba="0.7 0.4 0.2 1.0"/>
      </material>
    </visual>
  </link>
  <link name="r_f1_1">
    <origin rpy="0 0 0" xyz="0 0 0"/>
    <inertial>
      <mass value="0.1"/>
      <origin xyz="0 0 0"/>
      <inertia ixx="0.01" ixy="0" ixz="0" iyy="0.01" iyz="0" izz="0.01"/>
    </inertial>
    <collision>
      <origin rpy="0 0 0" xyz="0 0 0"/>
      <geometry>
        <mesh filename="camhand/f1.stl"/>
      </geometry>
    </collision>
    <visual>
      <origin rpy="0 0 0" xyz="0 0 0"/>
      <geometry>
        <mesh filename="camhand/f1.stl"/>
      </geometry>
      <material name="r_camhand_skin">
        <color rgba="0.835 0.655 0.345 1.0"/>
      </material>
    </visual>
  </link>
  <link name="r_f1_1_accel">
    <origin rpy="0 0 0" xyz="0 0 0"/>
    <inertial>
      <mass value="0.1"/>
      <origin xyz="0 0 0"/>
      <inertia ixx="0.01" ixy="0" ixz="0" iyy="0.01" iyz="0" izz="0.01"/>
    </inertial>
  </link>
  <link name="r_f1_2">
    <origin rpy="0 0 0" xyz="0 0 0"/>
    <inertial>
      <mass value="0.1"/>
      <origin xyz="0 0 0"/>
      <inertia ixx="0.01" ixy="0" ixz="0" iyy="0.01" iyz="0" izz="0.01"/>
    </inertial>
    <collision>
      <origin rpy="0 0 0" xyz="0 0 0"/>
      <geometry>
        <mesh filename="camhand/f2.stl"/>
      </geometry>
    </collision>
    <visual>
      <origin rpy="0 0 0" xyz="0 0 0"/>
      <geometry>
        <mesh filename="camhand/f2.stl"/>
      </geometry>
      <material name="r_camhand_skin_suntan">
        <color rgba="0.8 0.6 0.3 1.0"/>
      </material>
    </visual>
  </link>
  <link name="r_f1_2_accel">
    <origin rpy="0 0 0" xyz="0 0 0"/>
    <inertial>
      <mass value="0.1"/>
      <origin xyz="0 0 0"/>
      <inertia ixx="0.01" ixy="0" ixz="0" iyy="0.01" iyz="0" izz="0.01"/>
    </inertial>
  </link>
  <joint name="r_f1_base" type="fixed">
    <parent link="r_palm"/>
    <child link="r_f1_base"/>
    <origin rpy="0 0 0.3" xyz="0.115 0.03122 0"/>
  </joint>
  <joint name="r_f1_j0" type="revolute">
    <axis xyz="0 0 1"/>
    <parent link="r_f1_base"/>
    <child link="r_f1_0"/>
    <limit effort="1" lower="-1.57079" upper="1.57079" velocity="1"/>
    <origin rpy="0 0 0" xyz="0 0 0"/>
  </joint>
  <joint name="r_f1_j1" type="revolute">
    <axis xyz="0 0 1"/>
    <parent link="r_f1_0"/>
    <child link="r_f1_1"/>
    <limit effort="1" lower="-1.57079" upper="1.57079" velocity="1"/>
    <origin rpy="1.57079 0 0" xyz="0.028 0 0"/>
  </joint>
  <joint name="r_f1_j2" type="revolute">
    <axis xyz="0 0 1"/>
    <parent link="r_f1_1"/>
    <child link="r_f1_2"/>
    <origin rpy="0 0 0" xyz="0.05 0 0"/>
    <limit effort="1" lower="-1.57079" upper="1.57079" velocity="1"/>
  </joint>
  <joint name="r_f1_fixed_accel" type="fixed">
    <parent link="r_f1_base"/>
    <child link="r_f1_fixed_accel"/>
    <origin rpy="0 0 0" xyz="-0.05 0 0"/>
  </joint>
  <joint name="r_f1_1_accel" type="fixed">
    <parent link="r_f1_1"/>
    <child link="r_f1_1_accel"/>
    <origin rpy="-1.5709 0 0" xyz="0.03 0 0"/>
  </joint>
  <joint name="r_f1_2_accel" type="fixed">
    <parent link="r_f1_2"/>
    <child link="r_f1_2_accel"/>
    <origin rpy="-1.5709 0 0" xyz="0.04 0 0"/>
  </joint>
  <link name="r_f2_base">
    <origin rpy="0 0 0" xyz="0 0 0"/>
    <inertial>
      <mass value="0.1"/>
      <origin xyz="0 0 0"/>
      <inertia ixx="0.01" ixy="0" ixz="0" iyy="0.01" iyz="0" izz="0.01"/>
    </inertial>
  </link>
  <link name="r_f2_fixed_accel">
    <origin rpy="0 0 0" xyz="0 0 0"/>
    <inertial>
      <mass value="0.1"/>
      <origin xyz="0 0 0"/>
      <inertia ixx="0.01" ixy="0" ixz="0" iyy="0.01" iyz="0" izz="0.01"/>
    </inertial>
  </link>
  <link name="r_f2_0">
    <origin rpy="0 0 0" xyz="0 0 0"/>
    <inertial>
      <mass value="0.1"/>
      <origin xyz="0 0 0"/>
      <inertia ixx="0.01" ixy="0" ixz="0" iyy="0.01" iyz="0" izz="0.01"/>
    </inertial>
    <collision>
      <origin rpy="0 0 0" xyz="0 0 0"/>
      <geometry>
        <mesh filename="camhand/f0.stl"/>
      </geometry>
    </collision>
    <visual>
      <origin rpy="0 0 0" xyz="0 0 0"/>
      <geometry>
        <mesh filename="camhand/f0.stl"/>
      </geometry>
      <material name="r_camhand_skin_suntan">
        <color rgba="0.7 0.4 0.2 1.0"/>
      </material>
    </visual>
  </link>
  <link name="r_f2_1">
    <origin rpy="0 0 0" xyz="0 0 0"/>
    <inertial>
      <mass value="0.1"/>
      <origin xyz="0 0 0"/>
      <inertia ixx="0.01" ixy="0" ixz="0" iyy="0.01" iyz="0" izz="0.01"/>
    </inertial>
    <collision>
      <origin rpy="0 0 0" xyz="0 0 0"/>
      <geometry>
        <mesh filename="camhand/f1.stl"/>
      </geometry>
    </collision>
    <visual>
      <origin rpy="0 0 0" xyz="0 0 0"/>
      <geometry>
        <mesh filename="camhand/f1.stl"/>
      </geometry>
      <material name="r_camhand_skin">
        <color rgba="0.835 0.655 0.345 1.0"/>
      </material>
    </visual>
  </link>
  <link name="r_f2_1_accel">
    <origin rpy="0 0 0" xyz="0 0 0"/>
    <inertial>
      <mass value="0.1"/>
      <origin xyz="0 0 0"/>
      <inertia ixx="0.01" ixy="0" ixz="0" iyy="0.01" iyz="0" izz="0.01"/>
    </inertial>
  </link>
  <link name="r_f2_2">
    <origin rpy="0 0 0" xyz="0 0 0"/>
    <inertial>
      <mass value="0.1"/>
      <origin xyz="0 0 0"/>
      <inertia ixx="0.01" ixy="0" ixz="0" iyy="0.01" iyz="0" izz="0.01"/>
    </inertial>
    <collision>
      <origin rpy="0 0 0" xyz="0 0 0"/>
      <geometry>
        <mesh filename="camhand/f2.stl"/>
      </geometry>
    </collision>
    <visual>
      <origin rpy="0 0 0" xyz="0 0 0"/>
      <geometry>
        <mesh filename="camhand/f2.stl"/>
      </geometry>
      <material name="r_camhand_skin_suntan">
        <color rgba="0.8 0.6 0.3 1.0"/>
      </material>
    </visual>
  </link>
  <link name="r_f2_2_accel">
    <origin rpy="0 0 0" xyz="0 0 0"/>
    <inertial>
      <mass value="0.1"/>
      <origin xyz="0 0 0"/>
      <inertia ixx="0.01" ixy="0" ixz="0" iyy="0.01" iyz="0" izz="0.01"/>
    </inertial>
  </link>
  <joint name="r_f2_base" type="fixed">
    <parent link="r_palm"/>
    <child link="r_f2_base"/>
    <origin rpy="0 0 0.3" xyz="0.09 0.06245 0"/>
  </joint>
  <joint name="r_f2_j0" type="revolute">
    <axis xyz="0 0 1"/>
    <parent link="r_f2_base"/>
    <child link="r_f2_0"/>
    <limit effort="1" lower="-1.57079" upper="1.57079" velocity="1"/>
    <origin rpy="0 0 0" xyz="0 0 0"/>
  </joint>
  <joint name="r_f2_j1" type="revolute">
    <axis xyz="0 0 1"/>
    <parent link="r_f2_0"/>
    <child link="r_f2_1"/>
    <limit effort="1" lower="-1.57079" upper="1.57079" velocity="1"/>
    <origin rpy="1.57079 0 0" xyz="0.028 0 0"/>
  </joint>
  <joint name="r_f2_j2" type="revolute">
    <axis xyz="0 0 1"/>
    <parent link="r_f2_1"/>
    <child link="r_f2_2"/>
    <origin rpy="0 0 0" xyz="0.05 0 0"/>
    <limit effort="1" lower="-1.57079" upper="1.57079" velocity="1"/>
  </joint>
  <joint name="r_f2_fixed_accel" type="fixed">
    <parent link="r_f2_base"/>
    <child link="r_f2_fixed_accel"/>
    <origin rpy="0 0 0" xyz="-0.05 0 0"/>
  </joint>
  <joint name="r_f2_1_accel" type="fixed">
    <parent link="r_f2_1"/>
    <child link="r_f2_1_accel"/>
    <origin rpy="-1.5709 0 0" xyz="0.03 0 0"/>
  </joint>
  <joint name="r_f2_2_accel" type="fixed">
    <parent link="r_f2_2"/>
    <child link="r_f2_2_accel"/>
    <origin rpy="-1.5709 0 0" xyz="0.04 0 0"/>
  </joint>
  <link name="r_f3_base">
    <origin rpy="0 0 0" xyz="0 0 0"/>
    <inertial>
      <mass value="0.1"/>
      <origin xyz="0 0 0"/>
      <inertia ixx="0.01" ixy="0" ixz="0" iyy="0.01" iyz="0" izz="0.01"/>
    </inertial>
  </link>
  <link name="r_f3_fixed_accel">
    <origin rpy="0 0 0" xyz="0 0 0"/>
    <inertial>
      <mass value="0.1"/>
      <origin xyz="0 0 0"/>
      <inertia ixx="0.01" ixy="0" ixz="0" iyy="0.01" iyz="0" izz="0.01"/>
    </inertial>
  </link>
  <link name="r_f3_0">
    <origin rpy="0 0 0" xyz="0 0 0"/>
    <inertial>
      <mass value="0.1"/>
      <origin xyz="0 0 0"/>
      <inertia ixx="0.01" ixy="0" ixz="0" iyy="0.01" iyz="0" izz="0.01"/>
    </inertial>
    <collision>
      <origin rpy="0 0 0" xyz="0 0 0"/>
      <geometry>
        <mesh filename="camhand/f0.stl"/>
      </geometry>
    </collision>
    <visual>
      <origin rpy="0 0 0" xyz="0 0 0"/>
      <geometry>
        <mesh filename="camhand/f0.stl"/>
      </geometry>
      <material name="r_camhand_skin_suntan">
        <color rgba="0.7 0.4 0.2 1.0"/>
      </material>
    </visual>
  </link>
  <link name="r_f3_1">
    <origin rpy="0 0 0" xyz="0 0 0"/>
    <inertial>
      <mass value="0.1"/>
      <origin xyz="0 0 0"/>
      <inertia ixx="0.01" ixy="0" ixz="0" iyy="0.01" iyz="0" izz="0.01"/>
    </inertial>
    <collision>
      <origin rpy="0 0 0" xyz="0 0 0"/>
      <geometry>
        <mesh filename="camhand/f1.stl"/>
      </geometry>
    </collision>
    <visual>
      <origin rpy="0 0 0" xyz="0 0 0"/>
      <geometry>
        <mesh filename="camhand/f1.stl"/>
      </geometry>
      <material name="r_camhand_skin">
        <color rgba="0.835 0.655 0.345 1.0"/>
      </material>
    </visual>
  </link>
  <link name="r_f3_1_accel">
    <origin rpy="0 0 0" xyz="0 0 0"/>
    <inertial>
      <mass value="0.1"/>
      <origin xyz="0 0 0"/>
      <inertia ixx="0.01" ixy="0" ixz="0" iyy="0.01" iyz="0" izz="0.01"/>
    </inertial>
  </link>
  <link name="r_f3_2">
    <origin rpy="0 0 0" xyz="0 0 0"/>
    <inertial>
      <mass value="0.1"/>
      <origin xyz="0 0 0"/>
      <inertia ixx="0.01" ixy="0" ixz="0" iyy="0.01" iyz="0" izz="0.01"/>
    </inertial>
    <collision>
      <origin rpy="0 0 0" xyz="0 0 0"/>
      <geometry>
        <mesh filename="camhand/f2.stl"/>
      </geometry>
    </collision>
    <visual>
      <origin rpy="0 0 0" xyz="0 0 0"/>
      <geometry>
        <mesh filename="camhand/f2.stl"/>
      </geometry>
      <material name="r_camhand_skin_suntan">
        <color rgba="0.8 0.6 0.3 1.0"/>
      </material>
    </visual>
  </link>
  <link name="r_f3_2_accel">
    <origin rpy="0 0 0" xyz="0 0 0"/>
    <inertial>
      <mass value="0.1"/>
      <origin xyz="0 0 0"/>
      <inertia ixx="0.01" ixy="0" ixz="0" iyy="0.01" iyz="0" izz="0.01"/>
    </inertial>
  </link>
  <joint name="r_f3_base" type="fixed">
    <parent link="r_palm"/>
    <child link="r_f3_base"/>
    <origin rpy="0 -1.57079 -2.3562" xyz="0.03995 -0.04383 0.014"/>
  </joint>
  <joint name="r_f3_j0" type="revolute">
    <axis xyz="0 0 1"/>
    <parent link="r_f3_base"/>
    <child link="r_f3_0"/>
    <limit effort="1" lower="-1.57079" upper="1.57079" velocity="1"/>
    <origin rpy="0 0 0" xyz="0 0 0"/>
  </joint>
  <joint name="r_f3_j1" type="revolute">
    <axis xyz="0 0 1"/>
    <parent link="r_f3_0"/>
    <child link="r_f3_1"/>
    <limit effort="1" lower="-1.57079" upper="1.57079" velocity="1"/>
    <origin rpy="1.57079 0 0" xyz="0.028 0 0"/>
  </joint>
  <joint name="r_f3_j2" type="revolute">
    <axis xyz="0 0 1"/>
    <parent link="r_f3_1"/>
    <child link="r_f3_2"/>
    <origin rpy="0 0 0" xyz="0.05 0 0"/>
    <limit effort="1" lower="-1.57079" upper="1.57079" velocity="1"/>
  </joint>
  <joint name="r_f3_fixed_accel" type="fixed">
    <parent link="r_f3_base"/>
    <child link="r_f3_fixed_accel"/>
    <origin rpy="0 0 0" xyz="-0.05 0 0"/>
  </joint>
  <joint name="r_f3_1_accel" type="fixed">
    <parent link="r_f3_1"/>
    <child link="r_f3_1_accel"/>
    <origin rpy="-1.5709 0 0" xyz="0.03 0 0"/>
  </joint>
  <joint name="r_f3_2_accel" type="fixed">
    <parent link="r_f3_2"/>
    <child link="r_f3_2_accel"/>
    <origin rpy="-1.5709 0 0" xyz="0.04 0 0"/>
  </joint>
  <link name="l_palm">
    <origin rpy="0 0 0" xyz="0 0 0"/>
    <inertial>
      <mass value="0.1"/>
      <origin xyz="0 0 0"/>
      <inertia ixx="0.01" ixy="0" ixz="0" iyy="0.01" iyz="0" izz="0.01"/>
    </inertial>
    <collision>
      <origin rpy="0 0 0" xyz="0 0 0"/>
      <geometry>
        <mesh filename="camhand/palm.stl"/>
      </geometry>
    </collision>
    <visual>
      <origin rpy="0 0 0" xyz="0 0 0"/>
      <geometry>
        <mesh filename="camhand/palm.stl"/>
      </geometry>
      <material name="l_camhand_skin">
        <color rgba="0.835 0.655 0.345 1.0"/>
      </material>
    </visual>
  </link>
  <joint name="l_camhand_joint" type="fixed">
    <parent link="l_hand"/>
    <child link="l_palm"/>
    <origin rpy="0 3.1416 -1.57079" xyz="0  0.1 -0.03"/>
  </joint>
  <link name="l_f0_base">
    <origin rpy="0 0 0" xyz="0 0 0"/>
    <inertial>
      <mass value="0.1"/>
      <origin xyz="0 0 0"/>
      <inertia ixx="0.01" ixy="0" ixz="0" iyy="0.01" iyz="0" izz="0.01"/>
    </inertial>
  </link>
  <link name="l_f0_fixed_accel">
    <origin rpy="0 0 0" xyz="0 0 0"/>
    <inertial>
      <mass value="0.1"/>
      <origin xyz="0 0 0"/>
      <inertia ixx="0.01" ixy="0" ixz="0" iyy="0.01" iyz="0" izz="0.01"/>
    </inertial>
  </link>
  <link name="l_f0_0">
    <origin rpy="0 0 0" xyz="0 0 0"/>
    <inertial>
      <mass value="0.1"/>
      <origin xyz="0 0 0"/>
      <inertia ixx="0.01" ixy="0" ixz="0" iyy="0.01" iyz="0" izz="0.01"/>
    </inertial>
    <collision>
      <origin rpy="0 0 0" xyz="0 0 0"/>
      <geometry>
        <mesh filename="camhand/f0.stl"/>
      </geometry>
    </collision>
    <visual>
      <origin rpy="0 0 0" xyz="0 0 0"/>
      <geometry>
        <mesh filename="camhand/f0.stl"/>
      </geometry>
      <material name="l_camhand_skin_suntan">
        <color rgba="0.7 0.4 0.2 1.0"/>
      </material>
    </visual>
  </link>
  <link name="l_f0_1">
    <origin rpy="0 0 0" xyz="0 0 0"/>
    <inertial>
      <mass value="0.1"/>
      <origin xyz="0 0 0"/>
      <inertia ixx="0.01" ixy="0" ixz="0" iyy="0.01" iyz="0" izz="0.01"/>
    </inertial>
    <collision>
      <origin rpy="0 0 0" xyz="0 0 0"/>
      <geometry>
        <mesh filename="camhand/f1.stl"/>
      </geometry>
    </collision>
    <visual>
      <origin rpy="0 0 0" xyz="0 0 0"/>
      <geometry>
        <mesh filename="camhand/f1.stl"/>
      </geometry>
      <material name="l_camhand_skin">
        <color rgba="0.835 0.655 0.345 1.0"/>
      </material>
    </visual>
  </link>
  <link name="l_f0_1_accel">
    <origin rpy="0 0 0" xyz="0 0 0"/>
    <inertial>
      <mass value="0.1"/>
      <origin xyz="0 0 0"/>
      <inertia ixx="0.01" ixy="0" ixz="0" iyy="0.01" iyz="0" izz="0.01"/>
    </inertial>
  </link>
  <link name="l_f0_2">
    <origin rpy="0 0 0" xyz="0 0 0"/>
    <inertial>
      <mass value="0.1"/>
      <origin xyz="0 0 0"/>
      <inertia ixx="0.01" ixy="0" ixz="0" iyy="0.01" iyz="0" izz="0.01"/>
    </inertial>
    <collision>
      <origin rpy="0 0 0" xyz="0 0 0"/>
      <geometry>
        <mesh filename="camhand/f2.stl"/>
      </geometry>
    </collision>
    <visual>
      <origin rpy="0 0 0" xyz="0 0 0"/>
      <geometry>
        <mesh filename="camhand/f2.stl"/>
      </geometry>
      <material name="l_camhand_skin_suntan">
        <color rgba="0.8 0.6 0.3 1.0"/>
      </material>
    </visual>
  </link>
  <link name="l_f0_2_accel">
    <origin rpy="0 0 0" xyz="0 0 0"/>
    <inertial>
      <mass value="0.1"/>
      <origin xyz="0 0 0"/>
      <inertia ixx="0.01" ixy="0" ixz="0" iyy="0.01" iyz="0" izz="0.01"/>
    </inertial>
  </link>
  <joint name="l_f0_base" type="fixed">
    <parent link="l_palm"/>
    <child link="l_f0_base"/>
    <origin rpy="0 0 0.3" xyz="0.14 0.0 0"/>
  </joint>
  <joint name="l_f0_j0" type="revolute">
    <axis xyz="0 0 1"/>
    <parent link="l_f0_base"/>
    <child link="l_f0_0"/>
    <limit effort="1" lower="-1.57079" upper="1.57079" velocity="1"/>
    <origin rpy="0 0 0" xyz="0 0 0"/>
  </joint>
  <joint name="l_f0_j1" type="revolute">
    <axis xyz="0 0 1"/>
    <parent link="l_f0_0"/>
    <child link="l_f0_1"/>
    <limit effort="1" lower="-1.57079" upper="1.57079" velocity="1"/>
    <origin rpy="1.57079 0 0" xyz="0.028 0 0"/>
  </joint>
  <joint name="l_f0_j2" type="revolute">
    <axis xyz="0 0 1"/>
    <parent link="l_f0_1"/>
    <child link="l_f0_2"/>
    <origin rpy="0 0 0" xyz="0.05 0 0"/>
    <limit effort="1" lower="-1.57079" upper="1.57079" velocity="1"/>
  </joint>
  <joint name="l_f0_fixed_accel" type="fixed">
    <parent link="l_f0_base"/>
    <child link="l_f0_fixed_accel"/>
    <origin rpy="0 0 0" xyz="-0.05 0 0"/>
  </joint>
  <joint name="l_f0_1_accel" type="fixed">
    <parent link="l_f0_1"/>
    <child link="l_f0_1_accel"/>
    <origin rpy="-1.5709 0 0" xyz="0.03 0 0"/>
  </joint>
  <joint name="l_f0_2_accel" type="fixed">
    <parent link="l_f0_2"/>
    <child link="l_f0_2_accel"/>
    <origin rpy="-1.5709 0 0" xyz="0.04 0 0"/>
  </joint>
  <link name="l_f1_base">
    <origin rpy="0 0 0" xyz="0 0 0"/>
    <inertial>
      <mass value="0.1"/>
      <origin xyz="0 0 0"/>
      <inertia ixx="0.01" ixy="0" ixz="0" iyy="0.01" iyz="0" izz="0.01"/>
    </inertial>
  </link>
  <link name="l_f1_fixed_accel">
    <origin rpy="0 0 0" xyz="0 0 0"/>
    <inertial>
      <mass value="0.1"/>
      <origin xyz="0 0 0"/>
      <inertia ixx="0.01" ixy="0" ixz="0" iyy="0.01" iyz="0" izz="0.01"/>
    </inertial>
  </link>
  <link name="l_f1_0">
    <origin rpy="0 0 0" xyz="0 0 0"/>
    <inertial>
      <mass value="0.1"/>
      <origin xyz="0 0 0"/>
      <inertia ixx="0.01" ixy="0" ixz="0" iyy="0.01" iyz="0" izz="0.01"/>
    </inertial>
    <collision>
      <origin rpy="0 0 0" xyz="0 0 0"/>
      <geometry>
        <mesh filename="camhand/f0.stl"/>
      </geometry>
    </collision>
    <visual>
      <origin rpy="0 0 0" xyz="0 0 0"/>
      <geometry>
        <mesh filename="camhand/f0.stl"/>
      </geometry>
      <material name="l_camhand_skin_suntan">
        <color rgba="0.7 0.4 0.2 1.0"/>
      </material>
    </visual>
  </link>
  <link name="l_f1_1">
    <origin rpy="0 0 0" xyz="0 0 0"/>
    <inertial>
      <mass value="0.1"/>
      <origin xyz="0 0 0"/>
      <inertia ixx="0.01" ixy="0" ixz="0" iyy="0.01" iyz="0" izz="0.01"/>
    </inertial>
    <collision>
      <origin rpy="0 0 0" xyz="0 0 0"/>
      <geometry>
        <mesh filename="camhand/f1.stl"/>
      </geometry>
    </collision>
    <visual>
      <origin rpy="0 0 0" xyz="0 0 0"/>
      <geometry>
        <mesh filename="camhand/f1.stl"/>
      </geometry>
      <material name="l_camhand_skin">
        <color rgba="0.835 0.655 0.345 1.0"/>
      </material>
    </visual>
  </link>
  <link name="l_f1_1_accel">
    <origin rpy="0 0 0" xyz="0 0 0"/>
    <inertial>
      <mass value="0.1"/>
      <origin xyz="0 0 0"/>
      <inertia ixx="0.01" ixy="0" ixz="0" iyy="0.01" iyz="0" izz="0.01"/>
    </inertial>
  </link>
  <link name="l_f1_2">
    <origin rpy="0 0 0" xyz="0 0 0"/>
    <inertial>
      <mass value="0.1"/>
      <origin xyz="0 0 0"/>
      <inertia ixx="0.01" ixy="0" ixz="0" iyy="0.01" iyz="0" izz="0.01"/>
    </inertial>
    <collision>
      <origin rpy="0 0 0" xyz="0 0 0"/>
      <geometry>
        <mesh filename="camhand/f2.stl"/>
      </geometry>
    </collision>
    <visual>
      <origin rpy="0 0 0" xyz="0 0 0"/>
      <geometry>
        <mesh filename="camhand/f2.stl"/>
      </geometry>
      <material name="l_camhand_skin_suntan">
        <color rgba="0.8 0.6 0.3 1.0"/>
      </material>
    </visual>
  </link>
  <link name="l_f1_2_accel">
    <origin rpy="0 0 0" xyz="0 0 0"/>
    <inertial>
      <mass value="0.1"/>
      <origin xyz="0 0 0"/>
      <inertia ixx="0.01" ixy="0" ixz="0" iyy="0.01" iyz="0" izz="0.01"/>
    </inertial>
  </link>
  <joint name="l_f1_base" type="fixed">
    <parent link="l_palm"/>
    <child link="l_f1_base"/>
    <origin rpy="0 0 0.3" xyz="0.115 0.03122 0"/>
  </joint>
  <joint name="l_f1_j0" type="revolute">
    <axis xyz="0 0 1"/>
    <parent link="l_f1_base"/>
    <child link="l_f1_0"/>
    <limit effort="1" lower="-1.57079" upper="1.57079" velocity="1"/>
    <origin rpy="0 0 0" xyz="0 0 0"/>
  </joint>
  <joint name="l_f1_j1" type="revolute">
    <axis xyz="0 0 1"/>
    <parent link="l_f1_0"/>
    <child link="l_f1_1"/>
    <limit effort="1" lower="-1.57079" upper="1.57079" velocity="1"/>
    <origin rpy="1.57079 0 0" xyz="0.028 0 0"/>
  </joint>
  <joint name="l_f1_j2" type="revolute">
    <axis xyz="0 0 1"/>
    <parent link="l_f1_1"/>
    <child link="l_f1_2"/>
    <origin rpy="0 0 0" xyz="0.05 0 0"/>
    <limit effort="1" lower="-1.57079" upper="1.57079" velocity="1"/>
  </joint>
  <joint name="l_f1_fixed_accel" type="fixed">
    <parent link="l_f1_base"/>
    <child link="l_f1_fixed_accel"/>
    <origin rpy="0 0 0" xyz="-0.05 0 0"/>
  </joint>
  <joint name="l_f1_1_accel" type="fixed">
    <parent link="l_f1_1"/>
    <child link="l_f1_1_accel"/>
    <origin rpy="-1.5709 0 0" xyz="0.03 0 0"/>
  </joint>
  <joint name="l_f1_2_accel" type="fixed">
    <parent link="l_f1_2"/>
    <child link="l_f1_2_accel"/>
    <origin rpy="-1.5709 0 0" xyz="0.04 0 0"/>
  </joint>
  <link name="l_f2_base">
    <origin rpy="0 0 0" xyz="0 0 0"/>
    <inertial>
      <mass value="0.1"/>
      <origin xyz="0 0 0"/>
      <inertia ixx="0.01" ixy="0" ixz="0" iyy="0.01" iyz="0" izz="0.01"/>
    </inertial>
  </link>
  <link name="l_f2_fixed_accel">
    <origin rpy="0 0 0" xyz="0 0 0"/>
    <inertial>
      <mass value="0.1"/>
      <origin xyz="0 0 0"/>
      <inertia ixx="0.01" ixy="0" ixz="0" iyy="0.01" iyz="0" izz="0.01"/>
    </inertial>
  </link>
  <link name="l_f2_0">
    <origin rpy="0 0 0" xyz="0 0 0"/>
    <inertial>
      <mass value="0.1"/>
      <origin xyz="0 0 0"/>
      <inertia ixx="0.01" ixy="0" ixz="0" iyy="0.01" iyz="0" izz="0.01"/>
    </inertial>
    <collision>
      <origin rpy="0 0 0" xyz="0 0 0"/>
      <geometry>
        <mesh filename="camhand/f0.stl"/>
      </geometry>
    </collision>
    <visual>
      <origin rpy="0 0 0" xyz="0 0 0"/>
      <geometry>
        <mesh filename="camhand/f0.stl"/>
      </geometry>
      <material name="l_camhand_skin_suntan">
        <color rgba="0.7 0.4 0.2 1.0"/>
      </material>
    </visual>
  </link>
  <link name="l_f2_1">
    <origin rpy="0 0 0" xyz="0 0 0"/>
    <inertial>
      <mass value="0.1"/>
      <origin xyz="0 0 0"/>
      <inertia ixx="0.01" ixy="0" ixz="0" iyy="0.01" iyz="0" izz="0.01"/>
    </inertial>
    <collision>
      <origin rpy="0 0 0" xyz="0 0 0"/>
      <geometry>
        <mesh filename="camhand/f1.stl"/>
      </geometry>
    </collision>
    <visual>
      <origin rpy="0 0 0" xyz="0 0 0"/>
      <geometry>
        <mesh filename="camhand/f1.stl"/>
      </geometry>
      <material name="l_camhand_skin">
        <color rgba="0.835 0.655 0.345 1.0"/>
      </material>
    </visual>
  </link>
  <link name="l_f2_1_accel">
    <origin rpy="0 0 0" xyz="0 0 0"/>
    <inertial>
      <mass value="0.1"/>
      <origin xyz="0 0 0"/>
      <inertia ixx="0.01" ixy="0" ixz="0" iyy="0.01" iyz="0" izz="0.01"/>
    </inertial>
  </link>
  <link name="l_f2_2">
    <origin rpy="0 0 0" xyz="0 0 0"/>
    <inertial>
      <mass value="0.1"/>
      <origin xyz="0 0 0"/>
      <inertia ixx="0.01" ixy="0" ixz="0" iyy="0.01" iyz="0" izz="0.01"/>
    </inertial>
    <collision>
      <origin rpy="0 0 0" xyz="0 0 0"/>
      <geometry>
        <mesh filename="camhand/f2.stl"/>
      </geometry>
    </collision>
    <visual>
      <origin rpy="0 0 0" xyz="0 0 0"/>
      <geometry>
        <mesh filename="camhand/f2.stl"/>
      </geometry>
      <material name="l_camhand_skin_suntan">
        <color rgba="0.8 0.6 0.3 1.0"/>
      </material>
    </visual>
  </link>
  <link name="l_f2_2_accel">
    <origin rpy="0 0 0" xyz="0 0 0"/>
    <inertial>
      <mass value="0.1"/>
      <origin xyz="0 0 0"/>
      <inertia ixx="0.01" ixy="0" ixz="0" iyy="0.01" iyz="0" izz="0.01"/>
    </inertial>
  </link>
  <joint name="l_f2_base" type="fixed">
    <parent link="l_palm"/>
    <child link="l_f2_base"/>
    <origin rpy="0 0 0.3" xyz="0.09 0.06245 0"/>
  </joint>
  <joint name="l_f2_j0" type="revolute">
    <axis xyz="0 0 1"/>
    <parent link="l_f2_base"/>
    <child link="l_f2_0"/>
    <limit effort="1" lower="-1.57079" upper="1.57079" velocity="1"/>
    <origin rpy="0 0 0" xyz="0 0 0"/>
  </joint>
  <joint name="l_f2_j1" type="revolute">
    <axis xyz="0 0 1"/>
    <parent link="l_f2_0"/>
    <child link="l_f2_1"/>
    <limit effort="1" lower="-1.57079" upper="1.57079" velocity="1"/>
    <origin rpy="1.57079 0 0" xyz="0.028 0 0"/>
  </joint>
  <joint name="l_f2_j2" type="revolute">
    <axis xyz="0 0 1"/>
    <parent link="l_f2_1"/>
    <child link="l_f2_2"/>
    <origin rpy="0 0 0" xyz="0.05 0 0"/>
    <limit effort="1" lower="-1.57079" upper="1.57079" velocity="1"/>
  </joint>
  <joint name="l_f2_fixed_accel" type="fixed">
    <parent link="l_f2_base"/>
    <child link="l_f2_fixed_accel"/>
    <origin rpy="0 0 0" xyz="-0.05 0 0"/>
  </joint>
  <joint name="l_f2_1_accel" type="fixed">
    <parent link="l_f2_1"/>
    <child link="l_f2_1_accel"/>
    <origin rpy="-1.5709 0 0" xyz="0.03 0 0"/>
  </joint>
  <joint name="l_f2_2_accel" type="fixed">
    <parent link="l_f2_2"/>
    <child link="l_f2_2_accel"/>
    <origin rpy="-1.5709 0 0" xyz="0.04 0 0"/>
  </joint>
  <link name="l_f3_base">
    <origin rpy="0 0 0" xyz="0 0 0"/>
    <inertial>
      <mass value="0.1"/>
      <origin xyz="0 0 0"/>
      <inertia ixx="0.01" ixy="0" ixz="0" iyy="0.01" iyz="0" izz="0.01"/>
    </inertial>
  </link>
  <link name="l_f3_fixed_accel">
    <origin rpy="0 0 0" xyz="0 0 0"/>
    <inertial>
      <mass value="0.1"/>
      <origin xyz="0 0 0"/>
      <inertia ixx="0.01" ixy="0" ixz="0" iyy="0.01" iyz="0" izz="0.01"/>
    </inertial>
  </link>
  <link name="l_f3_0">
    <origin rpy="0 0 0" xyz="0 0 0"/>
    <inertial>
      <mass value="0.1"/>
      <origin xyz="0 0 0"/>
      <inertia ixx="0.01" ixy="0" ixz="0" iyy="0.01" iyz="0" izz="0.01"/>
    </inertial>
    <collision>
      <origin rpy="0 0 0" xyz="0 0 0"/>
      <geometry>
        <mesh filename="camhand/f0.stl"/>
      </geometry>
    </collision>
    <visual>
      <origin rpy="0 0 0" xyz="0 0 0"/>
      <geometry>
        <mesh filename="camhand/f0.stl"/>
      </geometry>
      <material name="l_camhand_skin_suntan">
        <color rgba="0.7 0.4 0.2 1.0"/>
      </material>
    </visual>
  </link>
  <link name="l_f3_1">
    <origin rpy="0 0 0" xyz="0 0 0"/>
    <inertial>
      <mass value="0.1"/>
      <origin xyz="0 0 0"/>
      <inertia ixx="0.01" ixy="0" ixz="0" iyy="0.01" iyz="0" izz="0.01"/>
    </inertial>
    <collision>
      <origin rpy="0 0 0" xyz="0 0 0"/>
      <geometry>
        <mesh filename="camhand/f1.stl"/>
      </geometry>
    </collision>
    <visual>
      <origin rpy="0 0 0" xyz="0 0 0"/>
      <geometry>
        <mesh filename="camhand/f1.stl"/>
      </geometry>
      <material name="l_camhand_skin">
        <color rgba="0.835 0.655 0.345 1.0"/>
      </material>
    </visual>
  </link>
  <link name="l_f3_1_accel">
    <origin rpy="0 0 0" xyz="0 0 0"/>
    <inertial>
      <mass value="0.1"/>
      <origin xyz="0 0 0"/>
      <inertia ixx="0.01" ixy="0" ixz="0" iyy="0.01" iyz="0" izz="0.01"/>
    </inertial>
  </link>
  <link name="l_f3_2">
    <origin rpy="0 0 0" xyz="0 0 0"/>
    <inertial>
      <mass value="0.1"/>
      <origin xyz="0 0 0"/>
      <inertia ixx="0.01" ixy="0" ixz="0" iyy="0.01" iyz="0" izz="0.01"/>
    </inertial>
    <collision>
      <origin rpy="0 0 0" xyz="0 0 0"/>
      <geometry>
        <mesh filename="camhand/f2.stl"/>
      </geometry>
    </collision>
    <visual>
      <origin rpy="0 0 0" xyz="0 0 0"/>
      <geometry>
        <mesh filename="camhand/f2.stl"/>
      </geometry>
      <material name="l_camhand_skin_suntan">
        <color rgba="0.8 0.6 0.3 1.0"/>
      </material>
    </visual>
  </link>
  <link name="l_f3_2_accel">
    <origin rpy="0 0 0" xyz="0 0 0"/>
    <inertial>
      <mass value="0.1"/>
      <origin xyz="0 0 0"/>
      <inertia ixx="0.01" ixy="0" ixz="0" iyy="0.01" iyz="0" izz="0.01"/>
    </inertial>
  </link>
  <joint name="l_f3_base" type="fixed">
    <parent link="l_palm"/>
    <child link="l_f3_base"/>
    <origin rpy="0 -1.57079 -2.3562" xyz="0.03995 -0.04383 0.014"/>
  </joint>
  <joint name="l_f3_j0" type="revolute">
    <axis xyz="0 0 1"/>
    <parent link="l_f3_base"/>
    <child link="l_f3_0"/>
    <limit effort="1" lower="-1.57079" upper="1.57079" velocity="1"/>
    <origin rpy="0 0 0" xyz="0 0 0"/>
  </joint>
  <joint name="l_f3_j1" type="revolute">
    <axis xyz="0 0 1"/>
    <parent link="l_f3_0"/>
    <child link="l_f3_1"/>
    <limit effort="1" lower="-1.57079" upper="1.57079" velocity="1"/>
    <origin rpy="1.57079 0 0" xyz="0.028 0 0"/>
  </joint>
  <joint name="l_f3_j2" type="revolute">
    <axis xyz="0 0 1"/>
    <parent link="l_f3_1"/>
    <child link="l_f3_2"/>
    <origin rpy="0 0 0" xyz="0.05 0 0"/>
    <limit effort="1" lower="-1.57079" upper="1.57079" velocity="1"/>
  </joint>
  <joint name="l_f3_fixed_accel" type="fixed">
    <parent link="l_f3_base"/>
    <child link="l_f3_fixed_accel"/>
    <origin rpy="0 0 0" xyz="-0.05 0 0"/>
  </joint>
  <joint name="l_f3_1_accel" type="fixed">
    <parent link="l_f3_1"/>
    <child link="l_f3_1_accel"/>
    <origin rpy="-1.5709 0 0" xyz="0.03 0 0"/>
  </joint>
  <joint name="l_f3_2_accel" type="fixed">
    <parent link="l_f3_2"/>
    <child link="l_f3_2_accel"/>
    <origin rpy="-1.5709 0 0" xyz="0.04 0 0"/>
  </joint>
  <gazebo>
    <plugin filename="libDRCRobotPlugin.so" name="drc_robot_plugin"/>
    <plugin filename="libgazebo_ros_controller_manager.so" name="gazebo_ros_controller_manager">
      <alwaysOn>true</alwaysOn>
      <updateRate>1000.0</updateRate>
    </plugin>
  </gazebo>
  <transmission name="back.lbz_trans" type="pr2_mechanism_model/SimpleTransmission">
    <joint name="back.lbz"/>
    <actuator name="back.lbz_motor"/>
    <mechanicalReduction>1</mechanicalReduction>
  </transmission>
  <transmission name="back.mby_trans" type="pr2_mechanism_model/SimpleTransmission">
    <actuator name="back.mby_motor"/>
    <joint name="back.mby"/>
    <mechanicalReduction>1</mechanicalReduction>
  </transmission>
  <transmission name="back.ubx_trans" type="pr2_mechanism_model/SimpleTransmission">
    <actuator name="back.ubx_motor"/>
    <joint name="back.ubx"/>
    <mechanicalReduction>1</mechanicalReduction>
  </transmission>
  <transmission name="l.arm.elx_trans" type="pr2_mechanism_model/SimpleTransmission">
    <actuator name="l.arm.elx_motor"/>
    <joint name="l.arm.elx"/>
    <mechanicalReduction>1</mechanicalReduction>
  </transmission>
  <transmission name="l.arm.ely_trans" type="pr2_mechanism_model/SimpleTransmission">
    <actuator name="l.arm.ely_motor"/>
    <joint name="l.arm.ely"/>
    <mechanicalReduction>1</mechanicalReduction>
  </transmission>
  <transmission name="l.arm.mwx_trans" type="pr2_mechanism_model/SimpleTransmission">
    <actuator name="l.arm.mwx_motor"/>
    <joint name="l.arm.mwx"/>
    <mechanicalReduction>1</mechanicalReduction>
  </transmission>
  <transmission name="l.arm.shx_trans" type="pr2_mechanism_model/SimpleTransmission">
    <actuator name="l.arm.shx_motor"/>
    <joint name="l.arm.shx"/>
    <mechanicalReduction>1</mechanicalReduction>
  </transmission>
  <transmission name="l.arm.usy_trans" type="pr2_mechanism_model/SimpleTransmission">
    <actuator name="l.arm.usy_motor"/>
    <joint name="l.arm.usy"/>
    <mechanicalReduction>1</mechanicalReduction>
  </transmission>
  <transmission name="l.arm.uwy_trans" type="pr2_mechanism_model/SimpleTransmission">
    <actuator name="l.arm.uwy_motor"/>
    <joint name="l.arm.uwy"/>
    <mechanicalReduction>1</mechanicalReduction>
  </transmission>
  <transmission name="l.leg.kny_trans" type="pr2_mechanism_model/SimpleTransmission">
    <actuator name="l.leg.kny_motor"/>
    <joint name="l.leg.kny"/>
    <mechanicalReduction>1</mechanicalReduction>
  </transmission>
  <transmission name="l.leg.lax_trans" type="pr2_mechanism_model/SimpleTransmission">
    <actuator name="l.leg.lax_motor"/>
    <joint name="l.leg.lax"/>
    <mechanicalReduction>1</mechanicalReduction>
  </transmission>
  <transmission name="l.leg.lhy_trans" type="pr2_mechanism_model/SimpleTransmission">
    <actuator name="l.leg.lhy_motor"/>
    <joint name="l.leg.lhy"/>
    <mechanicalReduction>1</mechanicalReduction>
  </transmission>
  <transmission name="l.leg.mhx_trans" type="pr2_mechanism_model/SimpleTransmission">
    <actuator name="l.leg.mhx_motor"/>
    <joint name="l.leg.mhx"/>
    <mechanicalReduction>1</mechanicalReduction>
  </transmission>
  <transmission name="l.leg.uay_trans" type="pr2_mechanism_model/SimpleTransmission">
    <actuator name="l.leg.uay_motor"/>
    <joint name="l.leg.uay"/>
    <mechanicalReduction>1</mechanicalReduction>
  </transmission>
  <transmission name="l.leg.uhz_trans" type="pr2_mechanism_model/SimpleTransmission">
    <actuator name="l.leg.uhz_motor"/>
    <joint name="l.leg.uhz"/>
    <mechanicalReduction>1</mechanicalReduction>
  </transmission>
  <transmission name="neck.ay_trans" type="pr2_mechanism_model/SimpleTransmission">
    <actuator name="neck.ay_motor"/>
    <joint name="neck.ay"/>
    <mechanicalReduction>1</mechanicalReduction>
  </transmission>
  <transmission name="r.arm.elx_trans" type="pr2_mechanism_model/SimpleTransmission">
    <actuator name="r.arm.elx_motor"/>
    <joint name="r.arm.elx"/>
    <mechanicalReduction>1</mechanicalReduction>
  </transmission>
  <transmission name="r.arm.ely_trans" type="pr2_mechanism_model/SimpleTransmission">
    <actuator name="r.arm.ely_motor"/>
    <joint name="r.arm.ely"/>
    <mechanicalReduction>1</mechanicalReduction>
  </transmission>
  <transmission name="r.arm.mwx_trans" type="pr2_mechanism_model/SimpleTransmission">
    <actuator name="r.arm.mwx_motor"/>
    <joint name="r.arm.mwx"/>
    <mechanicalReduction>1</mechanicalReduction>
  </transmission>
  <transmission name="r.arm.shx_trans" type="pr2_mechanism_model/SimpleTransmission">
    <actuator name="r.arm.shx_motor"/>
    <joint name="r.arm.shx"/>
    <mechanicalReduction>1</mechanicalReduction>
  </transmission>
  <transmission name="r.arm.usy_trans" type="pr2_mechanism_model/SimpleTransmission">
    <actuator name="r.arm.usy_motor"/>
    <joint name="r.arm.usy"/>
    <mechanicalReduction>1</mechanicalReduction>
  </transmission>
  <transmission name="r.arm.uwy_trans" type="pr2_mechanism_model/SimpleTransmission">
    <actuator name="r.arm.uwy_motor"/>
    <joint name="r.arm.uwy"/>
    <mechanicalReduction>1</mechanicalReduction>
  </transmission>
  <transmission name="r.leg.kny_trans" type="pr2_mechanism_model/SimpleTransmission">
    <actuator name="r.leg.kny_motor"/>
    <joint name="r.leg.kny"/>
    <mechanicalReduction>1</mechanicalReduction>
  </transmission>
  <transmission name="r.leg.lax_trans" type="pr2_mechanism_model/SimpleTransmission">
    <actuator name="r.leg.lax_motor"/>
    <joint name="r.leg.lax"/>
    <mechanicalReduction>1</mechanicalReduction>
  </transmission>
  <transmission name="r.leg.lhy_trans" type="pr2_mechanism_model/SimpleTransmission">
    <actuator name="r.leg.lhy_motor"/>
    <joint name="r.leg.lhy"/>
    <mechanicalReduction>1</mechanicalReduction>
  </transmission>
  <transmission name="r.leg.mhx_trans" type="pr2_mechanism_model/SimpleTransmission">
    <actuator name="r.leg.mhx_motor"/>
    <joint name="r.leg.mhx"/>
    <mechanicalReduction>1</mechanicalReduction>
  </transmission>
  <transmission name="r.leg.uay_trans" type="pr2_mechanism_model/SimpleTransmission">
    <actuator name="r.leg.uay_motor"/>
    <joint name="r.leg.uay"/>
    <mechanicalReduction>1</mechanicalReduction>
  </transmission>
  <transmission name="r.leg.uhz_trans" type="pr2_mechanism_model/SimpleTransmission">
    <actuator name="r.leg.uhz_motor"/>
    <joint name="r.leg.uhz"/>
    <mechanicalReduction>1</mechanicalReduction>
  </transmission>
</robot>

