<?xml version="1.0" ?>
<gazebo version='1.2'>
  <model name='car'>
    <link name='chassis'>
      <!-- mesh width 51.1811 -->
      <!-- mesh height 99.8878 -->
      <!-- mesh origin at corner -->
      <inertial>
        <mass>500</mass>
        <pose>0 0 0 0 0 0</pose>
        <inertia>
          <ixx>10</ixx>
          <ixy>0</ixy>
          <ixz>0</ixz>
          <iyy>10</iyy>
          <iyz>0</iyz>
          <izz>10</izz>
        </inertia>
      </inertial>
      <!-- decompose into simple geom
      <collision name='chassis_collision'>
        <pose>-1.498 -0.7677165 0.200000 0.000000 -0.000000 -1.57079</pose>
        <geometry>
          <mesh>
            <uri>model://low_poly_golf_cart/meshes/no_wheels.dae</uri>
            <scale>0.030 0.030 0.030</scale>
          </mesh>
        </geometry>
      </collision>
      -->

      <visual name='chassis_visual'>
        <pose>-1.498 -0.7677165 0.200000 0.000000 -0.000000 -1.57079</pose>
        <geometry>
          <mesh>
            <uri>model://low_poly_golf_cart/meshes/no_wheels.dae</uri>
            <scale>0.030 0.030 0.030</scale>
          </mesh>
        </geometry>
      </visual>

      <!-- chassis base visual
      <visual name='chassis_base_vis'>
        <pose>0.0 0.0 0.350000 0.000000 0 0</pose>
        <geometry>
          <box>
            <size>3.0 1.7 0.09</size>
          </box>
        </geometry>
      </visual>
      -->

      <collision name='chassis_base_col'>
        <pose>0.0 0.0 0.350000 0.000000 0 0</pose>
        <geometry>
          <box>
            <size>3.0 1.7 0.09</size>
          </box>
        </geometry>
      </collision>

      <!-- box seat
      <visual name='chassis_seat_vis'>
        <pose>0.4 0.0 0.50000 0.000000 0 0</pose>
        <geometry>
          <box>
            <size>0.25 1.7 0.15</size>
          </box>
        </geometry>
      </visual>
      -->
      <collision name='chassis_seat_col'>
        <pose>0.4 0.0 0.50000 0.000000 0 0</pose>
        <geometry>
          <box>
            <size>0.25 1.7 0.15</size>
          </box>
        </geometry>
      </collision>

      <!-- box seat back
      <visual name='chassis_seat_back_vis'>
        <pose>0.25 0.0 0.70000 0.000000 0 0</pose>
        <geometry>
          <box>
            <size>0.05 1.7 0.5</size>
          </box>
        </geometry>
      </visual>
      -->
      <collision name='chassis_seat_back_col'>
        <pose>0.25 0.0 0.70000 0.000000 0 0</pose>
        <geometry>
          <box>
            <size>0.05 1.7 0.5</size>
          </box>
        </geometry>
      </collision>

      <velocity_decay/>
    </link>
    <link name='front_left_wheel_steering_block'>
      <pose>1.250000 0.717700 0.300000 -0.000000 1.570700 1.570700</pose>
      <inertial>
        <mass>10</mass>
        <pose>0 0 0 0 0 0</pose>
        <inertia>
          <ixx>1</ixx>
          <ixy>0</ixy>
          <ixz>0</ixz>
          <iyy>1</iyy>
          <iyz>0</iyz>
          <izz>1</izz>
        </inertia>
      </inertial>
      <collision name='front_left_wheel_collision'>
        <geometry>
          <cylinder>
            <radius>0.050000</radius>
            <length>0.010000</length>
          </cylinder>
        </geometry>
      </collision>
      <visual name='front_left_wheel_visual'>
        <geometry>
          <cylinder>
            <radius>0.050000</radius>
            <length>0.010000</length>
          </cylinder>
        </geometry>
        <material>
          <script>
            <uri>file://media/materials/scripts/gazebo.material</uri>
            <name>Gazebo/Black</name>
          </script>
        </material>
      </visual>
      <velocity_decay/>
    </link>
    <link name='front_right_wheel_steering_block'>
      <pose>1.250000 -0.717700 0.300000 -0.000000 1.570700 1.570700</pose>
      <inertial>
        <mass>10</mass>
        <pose>0 0 0 0 0 0</pose>
        <inertia>
          <ixx>1</ixx>
          <ixy>0</ixy>
          <ixz>0</ixz>
          <iyy>1</iyy>
          <iyz>0</iyz>
          <izz>1</izz>
        </inertia>
      </inertial>
      <collision name='front_right_wheel_collision'>
        <geometry>
          <cylinder>
            <radius>0.050000</radius>
            <length>0.010000</length>
          </cylinder>
        </geometry>
      </collision>
      <visual name='front_right_wheel_visual'>
        <geometry>
          <cylinder>
            <radius>0.050000</radius>
            <length>0.010000</length>
          </cylinder>
        </geometry>
        <material>
          <script>
            <uri>file://media/materials/scripts/gazebo.material</uri>
            <name>Gazebo/Black</name>
          </script>
        </material>
      </visual>
      <velocity_decay/>
    </link>
    <link name='front_left_wheel'>
      <pose>1.250000 0.817700 0.300000 -0.000000 1.570700 1.570700</pose>
      <inertial>
        <mass>10</mass>
        <pose>0 0 0 0 0 0</pose>
        <inertia>
          <ixx>1</ixx>
          <ixy>0</ixy>
          <ixz>0</ixz>
          <iyy>1</iyy>
          <iyz>0</iyz>
          <izz>1</izz>
        </inertia>
      </inertial>
      <collision name='front_left_wheel_collision'>
        <geometry>
          <cylinder>
            <radius>0.250000</radius>
            <length>0.100000</length>
          </cylinder>
        </geometry>
      </collision>
      <visual name='front_left_wheel_visual'>
        <geometry>
          <cylinder>
            <radius>0.250000</radius>
            <length>0.100000</length>
          </cylinder>
        </geometry>
        <material>
          <script>
            <uri>file://media/materials/scripts/gazebo.material</uri>
            <name>Gazebo/Black</name>
          </script>
        </material>
      </visual>
      <velocity_decay/>
    </link>
    <link name='front_right_wheel'>
      <pose>1.250000 -0.817700 0.300000 -0.000000 1.570700 1.570700</pose>
      <inertial>
        <mass>10</mass>
        <pose>0 0 0 0 0 0</pose>
        <inertia>
          <ixx>1</ixx>
          <ixy>0</ixy>
          <ixz>0</ixz>
          <iyy>1</iyy>
          <iyz>0</iyz>
          <izz>1</izz>
        </inertia>
      </inertial>
      <collision name='front_right_wheel_collision'>
        <geometry>
          <cylinder>
            <radius>0.250000</radius>
            <length>0.100000</length>
          </cylinder>
        </geometry>
      </collision>
      <visual name='front_right_wheel_visual'>
        <geometry>
          <cylinder>
            <radius>0.250000</radius>
            <length>0.100000</length>
          </cylinder>
        </geometry>
        <material>
          <script>
            <uri>file://media/materials/scripts/gazebo.material</uri>
            <name>Gazebo/Black</name>
          </script>
        </material>
      </visual>
      <velocity_decay/>
    </link>
    <link name='back_right_wheel'>
      <pose>-0.800000 -0.817700 0.300000 -0.000000 1.570700 1.570700</pose>
      <inertial>
        <mass>10</mass>
        <pose>0 0 0 0 0 0</pose>
        <inertia>
          <ixx>1</ixx>
          <ixy>0</ixy>
          <ixz>0</ixz>
          <iyy>1</iyy>
          <iyz>0</iyz>
          <izz>1</izz>
        </inertia>
      </inertial>
      <collision name='back_right_wheel_collision'>
        <geometry>
          <cylinder>
            <radius>0.250000</radius>
            <length>0.100000</length>
          </cylinder>
        </geometry>
      </collision>
      <visual name='back_right_wheel_visual'>
        <geometry>
          <cylinder>
            <radius>0.250000</radius>
            <length>0.100000</length>
          </cylinder>
        </geometry>
        <material>
          <script>
            <uri>file://media/materials/scripts/gazebo.material</uri>
            <name>Gazebo/Black</name>
          </script>
        </material>
      </visual>
      <velocity_decay/>
    </link>
    <link name='back_left_wheel'>
      <pose>-0.800000 0.817700 0.300000 -0.000000 1.570700 1.570700</pose>
      <inertial>
        <mass>10</mass>
        <pose>0 0 0 0 0 0</pose>
        <inertia>
          <ixx>1</ixx>
          <ixy>0</ixy>
          <ixz>0</ixz>
          <iyy>1</iyy>
          <iyz>0</iyz>
          <izz>1</izz>
        </inertia>
      </inertial>
      <collision name='back_left_wheel_collision'>
        <geometry>
          <cylinder>
            <radius>0.250000</radius>
            <length>0.100000</length>
          </cylinder>
        </geometry>
      </collision>
      <visual name='back_left_wheel_visual'>
        <geometry>
          <cylinder>
            <radius>0.250000</radius>
            <length>0.100000</length>
          </cylinder>
        </geometry>
        <material>
          <script>
            <uri>file://media/materials/scripts/gazebo.material</uri>
            <name>Gazebo/Black</name>
          </script>
        </material>
      </visual>
      <velocity_decay/>
    </link>
    <link name='gas_pedal'>
      <pose>0.800000 0.240000 0.550000 0.000000 -0.5 0.000000</pose>
      <inertial>
        <mass>1</mass>
        <pose>0 0 0 0 0 0</pose>
        <inertia>
          <ixx>0.01</ixx>
          <ixy>0</ixy>
          <ixz>0</ixz>
          <iyy>0.01</iyy>
          <iyz>0</iyz>
          <izz>0.01</izz>
        </inertia>
      </inertial>
      <collision name='gas_pedal_collision'>
        <geometry>
          <box>
            <size>0.160000 0.070000 0.020000</size>
          </box>
        </geometry>
      </collision>
      <visual name='gas_pedal_visual'>
        <geometry>
          <box>
            <size>0.160000 0.070000 0.020000</size>
          </box>
        </geometry>
        <material>
          <script>
            <uri>file://media/materials/scripts/gazebo.material</uri>
            <name>Gazebo/Red</name>
          </script>
          <ambient>0.2 0.2 0.2 1</ambient>
          <diffuse>0.2 0.2 0.2 1</diffuse>
          <specular>0.2 0.2 0.2 1</specular>
          <emissive>0.5 0.0 0.0 1</emissive>
        </material>
      </visual>
      <velocity_decay/>
    </link>
    <link name='brake_pedal'>
      <pose>0.850000 0.395000 0.570000 0.000000 0.300000 0.000000</pose>
      <inertial>
        <mass>1</mass>
        <pose>0 0 0 0 0 0</pose>
        <inertia>
          <ixx>0.01</ixx>
          <ixy>0</ixy>
          <ixz>0</ixz>
          <iyy>0.01</iyy>
          <iyz>0</iyz>
          <izz>0.01</izz>
        </inertia>
      </inertial>
      <collision name='brake_pedal_collision'>
        <geometry>
          <box>
            <size>0.020000 0.100000 0.030000</size>
          </box>
        </geometry>
      </collision>
      <visual name='brake_pedal_visual'>
        <geometry>
          <box>
            <size>0.020000 0.100000 0.030000</size>
          </box>
        </geometry>
        <material>
          <script>
            <uri>file://media/materials/scripts/gazebo.material</uri>
            <name>Gazebo/Blue</name>
          </script>
          <ambient>0.2 0.2 0.2 1</ambient>
          <diffuse>0.2 0.2 0.2 1</diffuse>
          <specular>0.2 0.2 0.2 1</specular>
          <emissive>0.0 0.0 0.5 1</emissive>
        </material>
      </visual>
      <velocity_decay/>
    </link>
    <link name='steering_wheel'>
      <pose>0.780000 0.3500000 0.928000 0.000000 1.8 0.000000</pose>
      <inertial>
        <mass>1</mass>
        <pose>0 0 0 0 0 0</pose>
        <inertia>
          <ixx>0.01</ixx>
          <ixy>0</ixy>
          <ixz>0</ixz>
          <iyy>0.01</iyy>
          <iyz>0</iyz>
          <izz>0.01</izz>
        </inertia>
      </inertial>
      <collision name='steering_wheel_collision'>
        <geometry>
          <cylinder>
            <radius>0.150000</radius>
            <length>0.020000</length>
          </cylinder>
        </geometry>
      </collision>
      <visual name='steering_wheel_visual'>
        <geometry>
          <cylinder>
            <radius>0.150000</radius>
            <length>0.020000</length>
          </cylinder>
        </geometry>
        <material>
          <script>
            <uri>file://media/materials/scripts/gazebo.material</uri>
            <name>Gazebo/Blue</name>
          </script>
          <ambient>0.2 0.2 0.2 1</ambient>
          <diffuse>0.2 0.2 0.2 1</diffuse>
          <specular>0.2 0.2 0.2 1</specular>
          <emissive>0.0 0.5 0.0 1</emissive>
        </material>
      </visual>
      <velocity_decay/>
    </link>
    <joint name='gas_joint' type='prismatic'>
      <parent>chassis</parent>
      <child>gas_pedal</child>
      <axis>
        <xyz>1.000000 0.000000 -1.000000</xyz>
        <limit>
          <lower>0.000000</lower>
          <upper>0.090000</upper>
        </limit>
      </axis>
    </joint>
    <joint name='brake_joint' type='prismatic'>
      <parent>chassis</parent>
      <child>brake_pedal</child>
      <axis>
        <xyz>1.000000 0.000000 -0.600000</xyz>
        <limit>
          <lower>0.000000</lower>
          <upper>0.100000</upper>
        </limit>
      </axis>
    </joint>
    <joint name='steering_joint' type='revolute'>
      <parent>chassis</parent>
      <child>steering_wheel</child>
      <axis>
        <xyz>4.286262 0.000000 -1.000000</xyz>
        <limit>
          <lower>-7.853000</lower>
          <upper>7.853000</upper>
        </limit>
      </axis>
    </joint>

    <joint name='front_right_steering_joint' type='revolute'>
      <parent>chassis</parent>
      <child>front_right_wheel_steering_block</child>
      <axis>
        <xyz>0.000000 0.000000 1.000000</xyz>
        <limit>
          <lower>-1.000000</lower>
          <upper>1.000000</upper>
        </limit>
      </axis>
      <physics>
        <ode>
          <limit>
            <cfm>0.000000</cfm>
            <erp>0.900000</erp>
          </limit>
        </ode>
      </physics>
    </joint>

    <joint name='front_left_steering_joint' type='revolute'>
      <parent>chassis</parent>
      <child>front_left_wheel_steering_block</child>
      <axis>
        <xyz>0.000000 0.000000 1.000000</xyz>
        <limit>
          <lower>-1.000000</lower>
          <upper>1.000000</upper>
        </limit>
      </axis>
      <physics>
        <ode>
          <limit>
            <cfm>0.000000</cfm>
            <erp>0.900000</erp>
          </limit>
        </ode>
      </physics>
    </joint>

    <joint name='front_left_joint' type='revolute'>
      <parent>front_left_wheel_steering_block</parent>
      <child>front_left_wheel</child>
      <axis>
        <xyz>0.000000 1.000000 0.000000</xyz>
      </axis>
      <physics>
        <ode>
          <limit>
            <cfm>0.000000</cfm>
            <erp>0.900000</erp>
          </limit>
        </ode>
      </physics>
    </joint>

    <joint name='front_right_joint' type='revolute'>
      <parent>front_right_wheel_steering_block</parent>
      <child>front_right_wheel</child>
      <axis>
        <xyz>0.000000 1.000000 0.000000</xyz>
      </axis>
      <physics>
        <ode>
          <limit>
            <cfm>0.000000</cfm>
            <erp>0.900000</erp>
          </limit>
        </ode>
      </physics>
    </joint>
    <joint name='back_right_joint' type='revolute'>
      <parent>chassis</parent>
      <child>back_right_wheel</child>
      <axis>
        <xyz>0.000000 1.000000 0.000000</xyz>
      </axis>
      <physics>
        <ode>
          <limit>
            <cfm>0.000000</cfm>
            <erp>0.900000</erp>
          </limit>
        </ode>
      </physics>
    </joint>
    <joint name='back_left_joint' type='revolute'>
      <parent>chassis</parent>
      <child>back_left_wheel</child>
      <axis>
        <xyz>0.000000 1.000000 0.000000</xyz>
      </axis>
      <physics>
        <ode>
          <limit>
            <cfm>0.000000</cfm>
            <erp>0.900000</erp>
          </limit>
        </ode>
      </physics>
    </joint>
    <plugin name='vehicle' filename='libDRCVehiclePlugin.so'>
      <front_left>front_left_joint</front_left>
      <front_right>front_right_joint</front_right>
      <back_left>back_left_joint</back_left>
      <back_right>back_right_joint</back_right>
      <gas_pedal>gas_joint</gas_pedal>
      <brake_pedal>brake_joint</brake_pedal>
      <steering_wheel>steering_joint</steering_wheel>
      <front_power>10</front_power>
      <rear_power>10</rear_power>
      <tire_angle_range>0.5</tire_angle_range>
      <max_speed>10</max_speed>
      <aero_load>0.1</aero_load>
    </plugin>
  </model>
</gazebo>
