<gazebo version='1.0'>
  <model name='building' static='0'>
    <origin pose='0.000000 0.000000 1.4 0.000000 -0.000000 0.000000'/>
    <link name='wall_0' gravity='0' self_collide='0' kinematic='0'>
      <origin pose='0.000000 0.000000 0.000000 0.000000 -0.000000 0.000000'/>
      <inertial mass='10.000000' density='1.000000'>
        <origin pose='0.000000 0.000000 0.000000 0.000000 -0.000000 0.000000'/>
        <inertia ixx='0.100000' ixy='0.000000' ixz='0.000000' iyy='0.100000' iyz='0.000000' izz='0.100000'/>
      </inertial>
      <collision name='wall_0_geom' laser_retro='0.000000'>
        <origin pose='0.000000 0.000000 0.125000 0.000000 -0.000000 0.000000'/>
        <geometry>
          <box size='0.100000 0.500000 0.250000'/>
        </geometry>
        <surface>
          <friction>
            <ode mu='-1.000000' mu2='-1.000000' fdir1='0.000000 0.000000 0.000000' slip1='0.000000' slip2='0.000000'/>
          </friction>
          <bounce restitution_coefficient='0.000000' threshold='100000.000000'/>
          <contact>
            <ode soft_cfm='0.000000' soft_erp='0.200000' kp='1000000000000.000000' kd='1.000000' max_vel='0.000000' min_depth='0.001000'/>
          </contact>
        </surface>
      </collision>
      <visual name='wall_0_geom_visual' cast_shadows='1' laser_retro='0.000000' transparency='0.000000'>
        <origin pose='0.000000 0.000000 0.125000 0.000000 -0.000000 0.000000'/>
        <geometry>
          <box size='0.100000 0.500000 0.250000'/>
        </geometry>
      </visual>
    </link>
    <link name='wall_1' gravity='0' self_collide='0' kinematic='0'>
      <origin pose='10.000000 0.000000 0.000000 0.000000 -0.000000 0.000000'/>
      <inertial mass='10.000000' density='1.000000'>
        <origin pose='0.000000 0.000000 0.000000 0.000000 -0.000000 0.000000'/>
        <inertia ixx='0.100000' ixy='0.000000' ixz='0.000000' iyy='0.100000' iyz='0.000000' izz='0.100000'/>
      </inertial>
      <collision name='wall_1_geom' laser_retro='0.000000'>
        <origin pose='0.000000 0.000000 0.125000 0.000000 -0.000000 0.000000'/>
        <geometry>
          <box size='0.100000 0.500000 0.250000'/>
        </geometry>
        <surface>
          <friction>
            <ode mu='-1.000000' mu2='-1.000000' fdir1='0.000000 0.000000 0.000000' slip1='0.000000' slip2='0.000000'/>
          </friction>
          <bounce restitution_coefficient='0.000000' threshold='100000.000000'/>
          <contact>
            <ode soft_cfm='0.000000' soft_erp='0.200000' kp='1000000000000.000000' kd='1.000000' max_vel='0.000000' min_depth='0.001000'/>
          </contact>
        </surface>
      </collision>
      <visual name='wall_1_geom_visual' cast_shadows='1' laser_retro='0.000000' transparency='0.000000'>
        <origin pose='0.000000 0.000000 0.125000 0.000000 -0.000000 0.000000'/>
        <geometry>
          <box size='0.100000 0.500000 0.250000'/>
        </geometry>
      </visual>
    </link>
    <joint name='wall_1_joint' type='revolute'>
      <origin pose='0.000000 0.000000 0.000000 0.000000 -0.000000 0.000000'/>
      <parent link='wall_0'/>
      <child link='wall_1'/>
      <axis xyz='0.000000 0.000000 1.000000'>
        <dynamics damping='0.000000' friction='0.000000'/>
        <limit lower='-1.570000' upper='1.570000' effort='0.000000' velocity='0.000000'/>
      </axis>
    </joint>
    <plugin filename="libmodify_building.so" name="modify_building"/>
  </model>
</gazebo>
