<?xml version="1.0" ?>
<robot name="fire_hose">
  <link name="link_00">
    <inertial>
      <mass value="0.1"/>
      <origin rpy="0 0 0" xyz="0 0 0"/>
      <inertia ixx="0.01" ixy="0" ixz="0" iyy="0.01" iyz="0" izz="0.01"/>
    </inertial>
    <visual>
      <origin rpy="0 1.57079 0" xyz="0.05 0 0"/>
      <geometry>
        <cylinder radius="0.025" length="0.1" />
      </geometry>
    </visual>
    <collision>
      <origin rpy="0 1.57079 0" xyz="0.05 0 0"/>
      <geometry>
        <cylinder radius="0.025" length="0.1" />
      </geometry>
    </collision>
  </link>

  <link name="sphere_01">
    <inertial>
      <mass value="0.1"/>
      <origin rpy="0 0 0" xyz="0 0 0"/>
      <inertia ixx="0.01" ixy="0" ixz="0" iyy="0.01" iyz="0" izz="0.01"/>
    </inertial>
    <visual>
      <origin rpy="0 0 0" xyz="0 0 0"/>
      <geometry>
        <sphere radius="0.025" />
      </geometry>
    </visual>
    <collision>
      <origin rpy="0 0 0" xyz="0 0 0"/>
      <geometry>
        <sphere radius="0.025" />
      </geometry>
    </collision>
  </link>
  <link name="link_01">
    <inertial>
      <mass value="0.1"/>
      <origin rpy="0 0 0" xyz="0 0 0"/>
      <inertia ixx="0.01" ixy="0" ixz="0" iyy="0.01" iyz="0" izz="0.01"/>
    </inertial>
    <visual>
      <origin rpy="0 1.57079 0" xyz="0.05 0 0"/>
      <geometry>
        <cylinder radius="0.025" length="0.1" />
      </geometry>
    </visual>
    <collision>
      <origin rpy="0 1.57079 0" xyz="0.05 0 0"/>
      <geometry>
        <cylinder radius="0.025" length="0.1" />
      </geometry>
    </collision>
  </link>
  <joint name="joint_01_1" type="revolute">
    <origin rpy="0 0 0" xyz="0.1 0 0"/>
    <axis xyz="0 0 1"/>
    <parent link="link_00"/>
    <child link="sphere_01"/>
    <limit effort="100" lower="-0.7" upper="0.7" velocity="10"/>
  </joint>
  <joint name="joint_01_2" type="revolute">
    <origin rpy="0 0 0" xyz="0 0 0"/>
    <axis xyz="0 1 0"/>
    <parent link="sphere_01"/>
    <child link="link_01"/>
    <limit effort="100" lower="-0.7" upper="0.7" velocity="10"/>
  </joint>

  <link name="sphere_02">
    <inertial>
      <mass value="0.1"/>
      <origin rpy="0 0 0" xyz="0 0 0"/>
      <inertia ixx="0.01" ixy="0" ixz="0" iyy="0.01" iyz="0" izz="0.01"/>
    </inertial>
    <visual>
      <origin rpy="0 0 0" xyz="0 0 0"/>
      <geometry>
        <sphere radius="0.025" />
      </geometry>
    </visual>
    <collision>
      <origin rpy="0 0 0" xyz="0 0 0"/>
      <geometry>
        <sphere radius="0.025" />
      </geometry>
    </collision>
  </link>
  <link name="link_02">
    <inertial>
      <mass value="0.1"/>
      <origin rpy="0 0 0" xyz="0 0 0"/>
      <inertia ixx="0.01" ixy="0" ixz="0" iyy="0.01" iyz="0" izz="0.01"/>
    </inertial>
    <visual>
      <origin rpy="0 1.57079 0" xyz="0.05 0 0"/>
      <geometry>
        <cylinder radius="0.025" length="0.1" />
      </geometry>
    </visual>
    <collision>
      <origin rpy="0 1.57079 0" xyz="0.05 0 0"/>
      <geometry>
        <cylinder radius="0.025" length="0.1" />
      </geometry>
    </collision>
  </link>
  <joint name="joint_02_1" type="revolute">
    <origin rpy="0 0 0" xyz="0.1 0 0"/>
    <axis xyz="0 0 1"/>
    <parent link="link_01"/>
    <child link="sphere_02"/>
    <limit effort="100" lower="-0.7" upper="0.7" velocity="10"/>
  </joint>
  <joint name="joint_02_2" type="revolute">
    <origin rpy="0 0 0" xyz="0 0 0"/>
    <axis xyz="0 1 0"/>
    <parent link="sphere_02"/>
    <child link="link_02"/>
    <limit effort="100" lower="-0.7" upper="0.7" velocity="10"/>
  </joint>

  <link name="sphere_03">
    <inertial>
      <mass value="0.1"/>
      <origin rpy="0 0 0" xyz="0 0 0"/>
      <inertia ixx="0.01" ixy="0" ixz="0" iyy="0.01" iyz="0" izz="0.01"/>
    </inertial>
    <visual>
      <origin rpy="0 0 0" xyz="0 0 0"/>
      <geometry>
        <sphere radius="0.025" />
      </geometry>
    </visual>
    <collision>
      <origin rpy="0 0 0" xyz="0 0 0"/>
      <geometry>
        <sphere radius="0.025" />
      </geometry>
    </collision>
  </link>
  <link name="link_03">
    <inertial>
      <mass value="0.1"/>
      <origin rpy="0 0 0" xyz="0 0 0"/>
      <inertia ixx="0.01" ixy="0" ixz="0" iyy="0.01" iyz="0" izz="0.01"/>
    </inertial>
    <visual>
      <origin rpy="0 1.57079 0" xyz="0.05 0 0"/>
      <geometry>
        <cylinder radius="0.025" length="0.1" />
      </geometry>
    </visual>
    <collision>
      <origin rpy="0 1.57079 0" xyz="0.05 0 0"/>
      <geometry>
        <cylinder radius="0.025" length="0.1" />
      </geometry>
    </collision>
  </link>
  <joint name="joint_03_1" type="revolute">
    <origin rpy="0 0 0" xyz="0.1 0 0"/>
    <axis xyz="0 0 1"/>
    <parent link="link_02"/>
    <child link="sphere_03"/>
    <limit effort="100" lower="-0.7" upper="0.7" velocity="10"/>
  </joint>
  <joint name="joint_03_2" type="revolute">
    <origin rpy="0 0 0" xyz="0 0 0"/>
    <axis xyz="0 1 0"/>
    <parent link="sphere_03"/>
    <child link="link_03"/>
    <limit effort="100" lower="-0.7" upper="0.7" velocity="10"/>
  </joint>

  <link name="sphere_04">
    <inertial>
      <mass value="0.1"/>
      <origin rpy="0 0 0" xyz="0 0 0"/>
      <inertia ixx="0.01" ixy="0" ixz="0" iyy="0.01" iyz="0" izz="0.01"/>
    </inertial>
    <visual>
      <origin rpy="0 0 0" xyz="0 0 0"/>
      <geometry>
        <sphere radius="0.025" />
      </geometry>
    </visual>
    <collision>
      <origin rpy="0 0 0" xyz="0 0 0"/>
      <geometry>
        <sphere radius="0.025" />
      </geometry>
    </collision>
  </link>
  <link name="link_04">
    <inertial>
      <mass value="0.1"/>
      <origin rpy="0 0 0" xyz="0 0 0"/>
      <inertia ixx="0.01" ixy="0" ixz="0" iyy="0.01" iyz="0" izz="0.01"/>
    </inertial>
    <visual>
      <origin rpy="0 1.57079 0" xyz="0.05 0 0"/>
      <geometry>
        <cylinder radius="0.025" length="0.1" />
      </geometry>
    </visual>
    <collision>
      <origin rpy="0 1.57079 0" xyz="0.05 0 0"/>
      <geometry>
        <cylinder radius="0.025" length="0.1" />
      </geometry>
    </collision>
  </link>
  <joint name="joint_04_1" type="revolute">
    <origin rpy="0 0 0" xyz="0.1 0 0"/>
    <axis xyz="0 0 1"/>
    <parent link="link_03"/>
    <child link="sphere_04"/>
    <limit effort="100" lower="-0.7" upper="0.7" velocity="10"/>
  </joint>
  <joint name="joint_04_2" type="revolute">
    <origin rpy="0 0 0" xyz="0 0 0"/>
    <axis xyz="0 1 0"/>
    <parent link="sphere_04"/>
    <child link="link_04"/>
    <limit effort="100" lower="-0.7" upper="0.7" velocity="10"/>
  </joint>

  <link name="sphere_05">
    <inertial>
      <mass value="0.1"/>
      <origin rpy="0 0 0" xyz="0 0 0"/>
      <inertia ixx="0.01" ixy="0" ixz="0" iyy="0.01" iyz="0" izz="0.01"/>
    </inertial>
    <visual>
      <origin rpy="0 0 0" xyz="0 0 0"/>
      <geometry>
        <sphere radius="0.025" />
      </geometry>
    </visual>
    <collision>
      <origin rpy="0 0 0" xyz="0 0 0"/>
      <geometry>
        <sphere radius="0.025" />
      </geometry>
    </collision>
  </link>
  <link name="link_05">
    <inertial>
      <mass value="0.1"/>
      <origin rpy="0 0 0" xyz="0 0 0"/>
      <inertia ixx="0.01" ixy="0" ixz="0" iyy="0.01" iyz="0" izz="0.01"/>
    </inertial>
    <visual>
      <origin rpy="0 1.57079 0" xyz="0.05 0 0"/>
      <geometry>
        <cylinder radius="0.025" length="0.1" />
      </geometry>
    </visual>
    <collision>
      <origin rpy="0 1.57079 0" xyz="0.05 0 0"/>
      <geometry>
        <cylinder radius="0.025" length="0.1" />
      </geometry>
    </collision>
  </link>
  <joint name="joint_05_1" type="revolute">
    <origin rpy="0 0 0" xyz="0.1 0 0"/>
    <axis xyz="0 0 1"/>
    <parent link="link_04"/>
    <child link="sphere_05"/>
    <limit effort="100" lower="-0.7" upper="0.7" velocity="10"/>
  </joint>
  <joint name="joint_05_2" type="revolute">
    <origin rpy="0 0 0" xyz="0 0 0"/>
    <axis xyz="0 1 0"/>
    <parent link="sphere_05"/>
    <child link="link_05"/>
    <limit effort="100" lower="-0.7" upper="0.7" velocity="10"/>
  </joint>

  <link name="sphere_06">
    <inertial>
      <mass value="0.1"/>
      <origin rpy="0 0 0" xyz="0 0 0"/>
      <inertia ixx="0.01" ixy="0" ixz="0" iyy="0.01" iyz="0" izz="0.01"/>
    </inertial>
    <visual>
      <origin rpy="0 0 0" xyz="0 0 0"/>
      <geometry>
        <sphere radius="0.025" />
      </geometry>
    </visual>
    <collision>
      <origin rpy="0 0 0" xyz="0 0 0"/>
      <geometry>
        <sphere radius="0.025" />
      </geometry>
    </collision>
  </link>
  <link name="link_06">
    <inertial>
      <mass value="0.1"/>
      <origin rpy="0 0 0" xyz="0 0 0"/>
      <inertia ixx="0.01" ixy="0" ixz="0" iyy="0.01" iyz="0" izz="0.01"/>
    </inertial>
    <visual>
      <origin rpy="0 1.57079 0" xyz="0.05 0 0"/>
      <geometry>
        <cylinder radius="0.025" length="0.1" />
      </geometry>
    </visual>
    <collision>
      <origin rpy="0 1.57079 0" xyz="0.05 0 0"/>
      <geometry>
        <cylinder radius="0.025" length="0.1" />
      </geometry>
    </collision>
  </link>
  <joint name="joint_06_1" type="revolute">
    <origin rpy="0 0 0" xyz="0.1 0 0"/>
    <axis xyz="0 0 1"/>
    <parent link="link_05"/>
    <child link="sphere_06"/>
    <limit effort="100" lower="-0.7" upper="0.7" velocity="10"/>
  </joint>
  <joint name="joint_06_2" type="revolute">
    <origin rpy="0 0 0" xyz="0 0 0"/>
    <axis xyz="0 1 0"/>
    <parent link="sphere_06"/>
    <child link="link_06"/>
    <limit effort="100" lower="-0.7" upper="0.7" velocity="10"/>
  </joint>

  <link name="sphere_07">
    <inertial>
      <mass value="0.1"/>
      <origin rpy="0 0 0" xyz="0 0 0"/>
      <inertia ixx="0.01" ixy="0" ixz="0" iyy="0.01" iyz="0" izz="0.01"/>
    </inertial>
    <visual>
      <origin rpy="0 0 0" xyz="0 0 0"/>
      <geometry>
        <sphere radius="0.025" />
      </geometry>
    </visual>
    <collision>
      <origin rpy="0 0 0" xyz="0 0 0"/>
      <geometry>
        <sphere radius="0.025" />
      </geometry>
    </collision>
  </link>
  <link name="link_07">
    <inertial>
      <mass value="0.1"/>
      <origin rpy="0 0 0" xyz="0 0 0"/>
      <inertia ixx="0.01" ixy="0" ixz="0" iyy="0.01" iyz="0" izz="0.01"/>
    </inertial>
    <visual>
      <origin rpy="0 1.57079 0" xyz="0.05 0 0"/>
      <geometry>
        <cylinder radius="0.025" length="0.1" />
      </geometry>
    </visual>
    <collision>
      <origin rpy="0 1.57079 0" xyz="0.05 0 0"/>
      <geometry>
        <cylinder radius="0.025" length="0.1" />
      </geometry>
    </collision>
  </link>
  <joint name="joint_07_1" type="revolute">
    <origin rpy="0 0 0" xyz="0.1 0 0"/>
    <axis xyz="0 0 1"/>
    <parent link="link_06"/>
    <child link="sphere_07"/>
    <limit effort="100" lower="-0.7" upper="0.7" velocity="10"/>
  </joint>
  <joint name="joint_07_2" type="revolute">
    <origin rpy="0 0 0" xyz="0 0 0"/>
    <axis xyz="0 1 0"/>
    <parent link="sphere_07"/>
    <child link="link_07"/>
    <limit effort="100" lower="-0.7" upper="0.7" velocity="10"/>
  </joint>

  <link name="sphere_08">
    <inertial>
      <mass value="0.1"/>
      <origin rpy="0 0 0" xyz="0 0 0"/>
      <inertia ixx="0.01" ixy="0" ixz="0" iyy="0.01" iyz="0" izz="0.01"/>
    </inertial>
    <visual>
      <origin rpy="0 0 0" xyz="0 0 0"/>
      <geometry>
        <sphere radius="0.025" />
      </geometry>
    </visual>
    <collision>
      <origin rpy="0 0 0" xyz="0 0 0"/>
      <geometry>
        <sphere radius="0.025" />
      </geometry>
    </collision>
  </link>
  <link name="link_08">
    <inertial>
      <mass value="0.1"/>
      <origin rpy="0 0 0" xyz="0 0 0"/>
      <inertia ixx="0.01" ixy="0" ixz="0" iyy="0.01" iyz="0" izz="0.01"/>
    </inertial>
    <visual>
      <origin rpy="0 1.57079 0" xyz="0.05 0 0"/>
      <geometry>
        <cylinder radius="0.025" length="0.1" />
      </geometry>
    </visual>
    <collision>
      <origin rpy="0 1.57079 0" xyz="0.05 0 0"/>
      <geometry>
        <cylinder radius="0.025" length="0.1" />
      </geometry>
    </collision>
  </link>
  <joint name="joint_08_1" type="revolute">
    <origin rpy="0 0 0" xyz="0.1 0 0"/>
    <axis xyz="0 0 1"/>
    <parent link="link_07"/>
    <child link="sphere_08"/>
    <limit effort="100" lower="-0.7" upper="0.7" velocity="10"/>
  </joint>
  <joint name="joint_08_2" type="revolute">
    <origin rpy="0 0 0" xyz="0 0 0"/>
    <axis xyz="0 1 0"/>
    <parent link="sphere_08"/>
    <child link="link_08"/>
    <limit effort="100" lower="-0.7" upper="0.7" velocity="10"/>
  </joint>

  <link name="sphere_09">
    <inertial>
      <mass value="0.1"/>
      <origin rpy="0 0 0" xyz="0 0 0"/>
      <inertia ixx="0.01" ixy="0" ixz="0" iyy="0.01" iyz="0" izz="0.01"/>
    </inertial>
    <visual>
      <origin rpy="0 0 0" xyz="0 0 0"/>
      <geometry>
        <sphere radius="0.025" />
      </geometry>
    </visual>
    <collision>
      <origin rpy="0 0 0" xyz="0 0 0"/>
      <geometry>
        <sphere radius="0.025" />
      </geometry>
    </collision>
  </link>
  <link name="link_09">
    <inertial>
      <mass value="0.1"/>
      <origin rpy="0 0 0" xyz="0 0 0"/>
      <inertia ixx="0.01" ixy="0" ixz="0" iyy="0.01" iyz="0" izz="0.01"/>
    </inertial>
    <visual>
      <origin rpy="0 1.57079 0" xyz="0.05 0 0"/>
      <geometry>
        <cylinder radius="0.025" length="0.1" />
      </geometry>
    </visual>
    <collision>
      <origin rpy="0 1.57079 0" xyz="0.05 0 0"/>
      <geometry>
        <cylinder radius="0.025" length="0.1" />
      </geometry>
    </collision>
  </link>
  <joint name="joint_09_1" type="revolute">
    <origin rpy="0 0 0" xyz="0.1 0 0"/>
    <axis xyz="0 0 1"/>
    <parent link="link_08"/>
    <child link="sphere_09"/>
    <limit effort="100" lower="-0.7" upper="0.7" velocity="10"/>
  </joint>
  <joint name="joint_09_2" type="revolute">
    <origin rpy="0 0 0" xyz="0 0 0"/>
    <axis xyz="0 1 0"/>
    <parent link="sphere_09"/>
    <child link="link_09"/>
    <limit effort="100" lower="-0.7" upper="0.7" velocity="10"/>
  </joint>

  <link name="sphere_10">
    <inertial>
      <mass value="0.1"/>
      <origin rpy="0 0 0" xyz="0 0 0"/>
      <inertia ixx="0.01" ixy="0" ixz="0" iyy="0.01" iyz="0" izz="0.01"/>
    </inertial>
    <visual>
      <origin rpy="0 0 0" xyz="0 0 0"/>
      <geometry>
        <sphere radius="0.025" />
      </geometry>
    </visual>
    <collision>
      <origin rpy="0 0 0" xyz="0 0 0"/>
      <geometry>
        <sphere radius="0.025" />
      </geometry>
    </collision>
  </link>
  <link name="link_10">
    <inertial>
      <mass value="0.1"/>
      <origin rpy="0 0 0" xyz="0 0 0"/>
      <inertia ixx="0.01" ixy="0" ixz="0" iyy="0.01" iyz="0" izz="0.01"/>
    </inertial>
    <visual>
      <origin rpy="0 1.57079 0" xyz="0.05 0 0"/>
      <geometry>
        <cylinder radius="0.025" length="0.1" />
      </geometry>
    </visual>
    <collision>
      <origin rpy="0 1.57079 0" xyz="0.05 0 0"/>
      <geometry>
        <cylinder radius="0.025" length="0.1" />
      </geometry>
    </collision>
  </link>
  <joint name="joint_10_1" type="revolute">
    <origin rpy="0 0 0" xyz="0.1 0 0"/>
    <axis xyz="0 0 1"/>
    <parent link="link_09"/>
    <child link="sphere_10"/>
    <limit effort="100" lower="-0.7" upper="0.7" velocity="10"/>
  </joint>
  <joint name="joint_10_2" type="revolute">
    <origin rpy="0 0 0" xyz="0 0 0"/>
    <axis xyz="0 1 0"/>
    <parent link="sphere_10"/>
    <child link="link_10"/>
    <limit effort="100" lower="-0.7" upper="0.7" velocity="10"/>
  </joint>

  <link name="sphere_11">
    <inertial>
      <mass value="0.1"/>
      <origin rpy="0 0 0" xyz="0 0 0"/>
      <inertia ixx="0.01" ixy="0" ixz="0" iyy="0.01" iyz="0" izz="0.01"/>
    </inertial>
    <visual>
      <origin rpy="0 0 0" xyz="0 0 0"/>
      <geometry>
        <sphere radius="0.025" />
      </geometry>
    </visual>
    <collision>
      <origin rpy="0 0 0" xyz="0 0 0"/>
      <geometry>
        <sphere radius="0.025" />
      </geometry>
    </collision>
  </link>
  <link name="link_11">
    <inertial>
      <mass value="0.1"/>
      <origin rpy="0 0 0" xyz="0 0 0"/>
      <inertia ixx="0.01" ixy="0" ixz="0" iyy="0.01" iyz="0" izz="0.01"/>
    </inertial>
    <visual>
      <origin rpy="0 1.57079 0" xyz="0.05 0 0"/>
      <geometry>
        <cylinder radius="0.025" length="0.1" />
      </geometry>
    </visual>
    <collision>
      <origin rpy="0 1.57079 0" xyz="0.05 0 0"/>
      <geometry>
        <cylinder radius="0.025" length="0.1" />
      </geometry>
    </collision>
  </link>
  <joint name="joint_11_1" type="revolute">
    <origin rpy="0 0 0" xyz="0.1 0 0"/>
    <axis xyz="0 0 1"/>
    <parent link="link_10"/>
    <child link="sphere_11"/>
    <limit effort="100" lower="-0.7" upper="0.7" velocity="10"/>
  </joint>
  <joint name="joint_11_2" type="revolute">
    <origin rpy="0 0 0" xyz="0 0 0"/>
    <axis xyz="0 1 0"/>
    <parent link="sphere_11"/>
    <child link="link_11"/>
    <limit effort="100" lower="-0.7" upper="0.7" velocity="10"/>
  </joint>

  <link name="sphere_12">
    <inertial>
      <mass value="0.1"/>
      <origin rpy="0 0 0" xyz="0 0 0"/>
      <inertia ixx="0.01" ixy="0" ixz="0" iyy="0.01" iyz="0" izz="0.01"/>
    </inertial>
    <visual>
      <origin rpy="0 0 0" xyz="0 0 0"/>
      <geometry>
        <sphere radius="0.025" />
      </geometry>
    </visual>
    <collision>
      <origin rpy="0 0 0" xyz="0 0 0"/>
      <geometry>
        <sphere radius="0.025" />
      </geometry>
    </collision>
  </link>
  <link name="link_12">
    <inertial>
      <mass value="0.1"/>
      <origin rpy="0 0 0" xyz="0 0 0"/>
      <inertia ixx="0.01" ixy="0" ixz="0" iyy="0.01" iyz="0" izz="0.01"/>
    </inertial>
    <visual>
      <origin rpy="0 1.57079 0" xyz="0.05 0 0"/>
      <geometry>
        <cylinder radius="0.025" length="0.1" />
      </geometry>
    </visual>
    <collision>
      <origin rpy="0 1.57079 0" xyz="0.05 0 0"/>
      <geometry>
        <cylinder radius="0.025" length="0.1" />
      </geometry>
    </collision>
  </link>
  <joint name="joint_12_1" type="revolute">
    <origin rpy="0 0 0" xyz="0.1 0 0"/>
    <axis xyz="0 0 1"/>
    <parent link="link_11"/>
    <child link="sphere_12"/>
    <limit effort="100" lower="-0.7" upper="0.7" velocity="10"/>
  </joint>
  <joint name="joint_12_2" type="revolute">
    <origin rpy="0 0 0" xyz="0 0 0"/>
    <axis xyz="0 1 0"/>
    <parent link="sphere_12"/>
    <child link="link_12"/>
    <limit effort="100" lower="-0.7" upper="0.7" velocity="10"/>
  </joint>

  <link name="sphere_13">
    <inertial>
      <mass value="0.1"/>
      <origin rpy="0 0 0" xyz="0 0 0"/>
      <inertia ixx="0.01" ixy="0" ixz="0" iyy="0.01" iyz="0" izz="0.01"/>
    </inertial>
    <visual>
      <origin rpy="0 0 0" xyz="0 0 0"/>
      <geometry>
        <sphere radius="0.025" />
      </geometry>
    </visual>
    <collision>
      <origin rpy="0 0 0" xyz="0 0 0"/>
      <geometry>
        <sphere radius="0.025" />
      </geometry>
    </collision>
  </link>
  <link name="link_13">
    <inertial>
      <mass value="0.1"/>
      <origin rpy="0 0 0" xyz="0 0 0"/>
      <inertia ixx="0.01" ixy="0" ixz="0" iyy="0.01" iyz="0" izz="0.01"/>
    </inertial>
    <visual>
      <origin rpy="0 1.57079 0" xyz="0.05 0 0"/>
      <geometry>
        <cylinder radius="0.025" length="0.1" />
      </geometry>
    </visual>
    <collision>
      <origin rpy="0 1.57079 0" xyz="0.05 0 0"/>
      <geometry>
        <cylinder radius="0.025" length="0.1" />
      </geometry>
    </collision>
  </link>
  <joint name="joint_13_1" type="revolute">
    <origin rpy="0 0 0" xyz="0.1 0 0"/>
    <axis xyz="0 0 1"/>
    <parent link="link_12"/>
    <child link="sphere_13"/>
    <limit effort="100" lower="-0.7" upper="0.7" velocity="10"/>
  </joint>
  <joint name="joint_13_2" type="revolute">
    <origin rpy="0 0 0" xyz="0 0 0"/>
    <axis xyz="0 1 0"/>
    <parent link="sphere_13"/>
    <child link="link_13"/>
    <limit effort="100" lower="-0.7" upper="0.7" velocity="10"/>
  </joint>

  <link name="sphere_14">
    <inertial>
      <mass value="0.1"/>
      <origin rpy="0 0 0" xyz="0 0 0"/>
      <inertia ixx="0.01" ixy="0" ixz="0" iyy="0.01" iyz="0" izz="0.01"/>
    </inertial>
    <visual>
      <origin rpy="0 0 0" xyz="0 0 0"/>
      <geometry>
        <sphere radius="0.025" />
      </geometry>
    </visual>
    <collision>
      <origin rpy="0 0 0" xyz="0 0 0"/>
      <geometry>
        <sphere radius="0.025" />
      </geometry>
    </collision>
  </link>
  <link name="link_14">
    <inertial>
      <mass value="0.1"/>
      <origin rpy="0 0 0" xyz="0 0 0"/>
      <inertia ixx="0.01" ixy="0" ixz="0" iyy="0.01" iyz="0" izz="0.01"/>
    </inertial>
    <visual>
      <origin rpy="0 1.57079 0" xyz="0.05 0 0"/>
      <geometry>
        <cylinder radius="0.025" length="0.1" />
      </geometry>
    </visual>
    <collision>
      <origin rpy="0 1.57079 0" xyz="0.05 0 0"/>
      <geometry>
        <cylinder radius="0.025" length="0.1" />
      </geometry>
    </collision>
  </link>
  <joint name="joint_14_1" type="revolute">
    <origin rpy="0 0 0" xyz="0.1 0 0"/>
    <axis xyz="0 0 1"/>
    <parent link="link_13"/>
    <child link="sphere_14"/>
    <limit effort="100" lower="-0.7" upper="0.7" velocity="10"/>
  </joint>
  <joint name="joint_14_2" type="revolute">
    <origin rpy="0 0 0" xyz="0 0 0"/>
    <axis xyz="0 1 0"/>
    <parent link="sphere_14"/>
    <child link="link_14"/>
    <limit effort="100" lower="-0.7" upper="0.7" velocity="10"/>
  </joint>

  <link name="sphere_15">
    <inertial>
      <mass value="0.1"/>
      <origin rpy="0 0 0" xyz="0 0 0"/>
      <inertia ixx="0.01" ixy="0" ixz="0" iyy="0.01" iyz="0" izz="0.01"/>
    </inertial>
    <visual>
      <origin rpy="0 0 0" xyz="0 0 0"/>
      <geometry>
        <sphere radius="0.025" />
      </geometry>
    </visual>
    <collision>
      <origin rpy="0 0 0" xyz="0 0 0"/>
      <geometry>
        <sphere radius="0.025" />
      </geometry>
    </collision>
  </link>
  <link name="link_15">
    <inertial>
      <mass value="0.1"/>
      <origin rpy="0 0 0" xyz="0 0 0"/>
      <inertia ixx="0.01" ixy="0" ixz="0" iyy="0.01" iyz="0" izz="0.01"/>
    </inertial>
    <visual>
      <origin rpy="0 1.57079 0" xyz="0.05 0 0"/>
      <geometry>
        <cylinder radius="0.025" length="0.1" />
      </geometry>
    </visual>
    <collision>
      <origin rpy="0 1.57079 0" xyz="0.05 0 0"/>
      <geometry>
        <cylinder radius="0.025" length="0.1" />
      </geometry>
    </collision>
  </link>
  <joint name="joint_15_1" type="revolute">
    <origin rpy="0 0 0" xyz="0.1 0 0"/>
    <axis xyz="0 0 1"/>
    <parent link="link_14"/>
    <child link="sphere_15"/>
    <limit effort="100" lower="-0.7" upper="0.7" velocity="10"/>
  </joint>
  <joint name="joint_15_2" type="revolute">
    <origin rpy="0 0 0" xyz="0 0 0"/>
    <axis xyz="0 1 0"/>
    <parent link="sphere_15"/>
    <child link="link_15"/>
    <limit effort="100" lower="-0.7" upper="0.7" velocity="10"/>
  </joint>

  <link name="sphere_16">
    <inertial>
      <mass value="0.1"/>
      <origin rpy="0 0 0" xyz="0 0 0"/>
      <inertia ixx="0.01" ixy="0" ixz="0" iyy="0.01" iyz="0" izz="0.01"/>
    </inertial>
    <visual>
      <origin rpy="0 0 0" xyz="0 0 0"/>
      <geometry>
        <sphere radius="0.025" />
      </geometry>
    </visual>
    <collision>
      <origin rpy="0 0 0" xyz="0 0 0"/>
      <geometry>
        <sphere radius="0.025" />
      </geometry>
    </collision>
  </link>
  <link name="link_16">
    <inertial>
      <mass value="0.1"/>
      <origin rpy="0 0 0" xyz="0 0 0"/>
      <inertia ixx="0.01" ixy="0" ixz="0" iyy="0.01" iyz="0" izz="0.01"/>
    </inertial>
    <visual>
      <origin rpy="0 1.57079 0" xyz="0.05 0 0"/>
      <geometry>
        <cylinder radius="0.025" length="0.1" />
      </geometry>
    </visual>
    <collision>
      <origin rpy="0 1.57079 0" xyz="0.05 0 0"/>
      <geometry>
        <cylinder radius="0.025" length="0.1" />
      </geometry>
    </collision>
  </link>
  <joint name="joint_16_1" type="revolute">
    <origin rpy="0 0 0" xyz="0.1 0 0"/>
    <axis xyz="0 0 1"/>
    <parent link="link_15"/>
    <child link="sphere_16"/>
    <limit effort="100" lower="-0.7" upper="0.7" velocity="10"/>
  </joint>
  <joint name="joint_16_2" type="revolute">
    <origin rpy="0 0 0" xyz="0 0 0"/>
    <axis xyz="0 1 0"/>
    <parent link="sphere_16"/>
    <child link="link_16"/>
    <limit effort="100" lower="-0.7" upper="0.7" velocity="10"/>
  </joint>

  <link name="sphere_17">
    <inertial>
      <mass value="0.1"/>
      <origin rpy="0 0 0" xyz="0 0 0"/>
      <inertia ixx="0.01" ixy="0" ixz="0" iyy="0.01" iyz="0" izz="0.01"/>
    </inertial>
    <visual>
      <origin rpy="0 0 0" xyz="0 0 0"/>
      <geometry>
        <sphere radius="0.025" />
      </geometry>
    </visual>
    <collision>
      <origin rpy="0 0 0" xyz="0 0 0"/>
      <geometry>
        <sphere radius="0.025" />
      </geometry>
    </collision>
  </link>
  <link name="link_17">
    <inertial>
      <mass value="0.1"/>
      <origin rpy="0 0 0" xyz="0 0 0"/>
      <inertia ixx="0.01" ixy="0" ixz="0" iyy="0.01" iyz="0" izz="0.01"/>
    </inertial>
    <visual>
      <origin rpy="0 1.57079 0" xyz="0.05 0 0"/>
      <geometry>
        <cylinder radius="0.025" length="0.1" />
      </geometry>
    </visual>
    <collision>
      <origin rpy="0 1.57079 0" xyz="0.05 0 0"/>
      <geometry>
        <cylinder radius="0.025" length="0.1" />
      </geometry>
    </collision>
  </link>
  <joint name="joint_17_1" type="revolute">
    <origin rpy="0 0 0" xyz="0.1 0 0"/>
    <axis xyz="0 0 1"/>
    <parent link="link_16"/>
    <child link="sphere_17"/>
    <limit effort="100" lower="-0.7" upper="0.7" velocity="10"/>
  </joint>
  <joint name="joint_17_2" type="revolute">
    <origin rpy="0 0 0" xyz="0 0 0"/>
    <axis xyz="0 1 0"/>
    <parent link="sphere_17"/>
    <child link="link_17"/>
    <limit effort="100" lower="-0.7" upper="0.7" velocity="10"/>
  </joint>

  <link name="sphere_18">
    <inertial>
      <mass value="0.1"/>
      <origin rpy="0 0 0" xyz="0 0 0"/>
      <inertia ixx="0.01" ixy="0" ixz="0" iyy="0.01" iyz="0" izz="0.01"/>
    </inertial>
    <visual>
      <origin rpy="0 0 0" xyz="0 0 0"/>
      <geometry>
        <sphere radius="0.025" />
      </geometry>
    </visual>
    <collision>
      <origin rpy="0 0 0" xyz="0 0 0"/>
      <geometry>
        <sphere radius="0.025" />
      </geometry>
    </collision>
  </link>
  <link name="link_18">
    <inertial>
      <mass value="0.1"/>
      <origin rpy="0 0 0" xyz="0 0 0"/>
      <inertia ixx="0.01" ixy="0" ixz="0" iyy="0.01" iyz="0" izz="0.01"/>
    </inertial>
    <visual>
      <origin rpy="0 1.57079 0" xyz="0.05 0 0"/>
      <geometry>
        <cylinder radius="0.025" length="0.1" />
      </geometry>
    </visual>
    <collision>
      <origin rpy="0 1.57079 0" xyz="0.05 0 0"/>
      <geometry>
        <cylinder radius="0.025" length="0.1" />
      </geometry>
    </collision>
  </link>
  <joint name="joint_18_1" type="revolute">
    <origin rpy="0 0 0" xyz="0.1 0 0"/>
    <axis xyz="0 0 1"/>
    <parent link="link_17"/>
    <child link="sphere_18"/>
    <limit effort="100" lower="-0.7" upper="0.7" velocity="10"/>
  </joint>
  <joint name="joint_18_2" type="revolute">
    <origin rpy="0 0 0" xyz="0 0 0"/>
    <axis xyz="0 1 0"/>
    <parent link="sphere_18"/>
    <child link="link_18"/>
    <limit effort="100" lower="-0.7" upper="0.7" velocity="10"/>
  </joint>

  <link name="sphere_19">
    <inertial>
      <mass value="0.1"/>
      <origin rpy="0 0 0" xyz="0 0 0"/>
      <inertia ixx="0.01" ixy="0" ixz="0" iyy="0.01" iyz="0" izz="0.01"/>
    </inertial>
    <visual>
      <origin rpy="0 0 0" xyz="0 0 0"/>
      <geometry>
        <sphere radius="0.025" />
      </geometry>
    </visual>
    <collision>
      <origin rpy="0 0 0" xyz="0 0 0"/>
      <geometry>
        <sphere radius="0.025" />
      </geometry>
    </collision>
  </link>
  <link name="link_19">
    <inertial>
      <mass value="0.1"/>
      <origin rpy="0 0 0" xyz="0 0 0"/>
      <inertia ixx="0.01" ixy="0" ixz="0" iyy="0.01" iyz="0" izz="0.01"/>
    </inertial>
    <visual>
      <origin rpy="0 1.57079 0" xyz="0.05 0 0"/>
      <geometry>
        <cylinder radius="0.025" length="0.1" />
      </geometry>
    </visual>
    <collision>
      <origin rpy="0 1.57079 0" xyz="0.05 0 0"/>
      <geometry>
        <cylinder radius="0.025" length="0.1" />
      </geometry>
    </collision>
  </link>
  <joint name="joint_19_1" type="revolute">
    <origin rpy="0 0 0" xyz="0.1 0 0"/>
    <axis xyz="0 0 1"/>
    <parent link="link_18"/>
    <child link="sphere_19"/>
    <limit effort="100" lower="-0.7" upper="0.7" velocity="10"/>
  </joint>
  <joint name="joint_19_2" type="revolute">
    <origin rpy="0 0 0" xyz="0 0 0"/>
    <axis xyz="0 1 0"/>
    <parent link="sphere_19"/>
    <child link="link_19"/>
    <limit effort="100" lower="-0.7" upper="0.7" velocity="10"/>
  </joint>

  <link name="sphere_20">
    <inertial>
      <mass value="0.1"/>
      <origin rpy="0 0 0" xyz="0 0 0"/>
      <inertia ixx="0.01" ixy="0" ixz="0" iyy="0.01" iyz="0" izz="0.01"/>
    </inertial>
    <visual>
      <origin rpy="0 0 0" xyz="0 0 0"/>
      <geometry>
        <sphere radius="0.025" />
      </geometry>
    </visual>
    <collision>
      <origin rpy="0 0 0" xyz="0 0 0"/>
      <geometry>
        <sphere radius="0.025" />
      </geometry>
    </collision>
  </link>
  <link name="link_20">
    <inertial>
      <mass value="0.1"/>
      <origin rpy="0 0 0" xyz="0 0 0"/>
      <inertia ixx="0.01" ixy="0" ixz="0" iyy="0.01" iyz="0" izz="0.01"/>
    </inertial>
    <visual>
      <origin rpy="0 1.57079 0" xyz="0.05 0 0"/>
      <geometry>
        <cylinder radius="0.025" length="0.1" />
      </geometry>
    </visual>
    <collision>
      <origin rpy="0 1.57079 0" xyz="0.05 0 0"/>
      <geometry>
        <cylinder radius="0.025" length="0.1" />
      </geometry>
    </collision>
  </link>
  <joint name="joint_20_1" type="revolute">
    <origin rpy="0 0 0" xyz="0.1 0 0"/>
    <axis xyz="0 0 1"/>
    <parent link="link_19"/>
    <child link="sphere_20"/>
    <limit effort="100" lower="-0.7" upper="0.7" velocity="10"/>
  </joint>
  <joint name="joint_20_2" type="revolute">
    <origin rpy="0 0 0" xyz="0 0 0"/>
    <axis xyz="0 1 0"/>
    <parent link="sphere_20"/>
    <child link="link_20"/>
    <limit effort="100" lower="-0.7" upper="0.7" velocity="10"/>
  </joint>

</robot>

